Workbook

Sheet データファイル用
A1: Material Properties for hygrothermal analysis | G1: Moisture conductivity (kg/msPa) | K1: Absorption (kg/kg) | R1: Liquid diffusivity
A2: No | B2: Material | C2: Dry Density (kg/m3) | D2: Heat Capacity (J/(kg K)) | E2: Thermal Conductivity (W/(m K)) | F2: Air Permeability (m2) | G2: a | H2: b | I2: c | J2: d | K2: Parameter | L2: a | M2: b | N2: c | O2: d | P2: f | Q2: g | R2: 範囲分け数 | S2: 範囲(大) | T2: a | U2: b | V2: c | W2: d | X2: e | Y2: f | Z2: g | AA2: 範囲(小) | AB2: 範囲(大) | AC2: a | AD2: b | AE2: c | AF2: d | AG2: e | AH2: f | AI2: g | AJ2: 範囲(小) | AK2: 範囲(大) | AL2: a | AM2: b | AN2: c | AO2: d | AP2: e | AQ2: f | AR2: g
A3: 0 | B3: Air | C3: 1.2 | D3: 1000 | E3: 0.022 | F3: 1e-12 | G3: 0 | H3: 0 | I3: 0 | J3: 0 | K3: 1 | L3: 0 | M3: 0 | N3: 0 | O3: 0 | P3: 0 | Q3: 0 | R3: 0 | S3: 0 | T3: 0 | U3: 0 | V3: 0 | W3: 0 | X3: 0 | Y3: 0 | Z3: 0 | AA3: 0 | AB3: 0 | AC3: 0 | AD3: 0 | AE3: 0 | AF3: 0 | AG3: 0 | AH3: 0 | AI3: 0 | AJ3: 0 | AK3: 0 | AL3: 0 | AM3: 0 | AN3: 0 | AO3: 0 | AP3: 0 | AQ3: 0 | AR3: 0
A4: 1 | B4: MEWS Aerated Concrete | C4: 460 | D4: 840 | E4: 0.121 | F4: 6.9e-14 | G4: 6.1555e-11 | H4: 0.04535 | I4: -1.7048 | J4: 1.2049 | K4: 1 | L4: 0.78743 | M4: 17.297 | N4: -0.35107 | O4: 78.553 | P4: 0 | Q4: 0 | R4: 3 | S4: 0.087 | T4: -18.559943 | U4: 0 | V4: 0 | W4: 0 | X4: 0 | Y4: 0 | Z4: 0 | AA4: 0.087 | AB4: 0.54 | AC4: -15.073 | AD4: -63.312 | AE4: 324.96 | AF4: -731.86 | AG4: 623.3 | AH4: 0 | AI4: 0 | AJ4: 0.54 | AK4: 1.3 | AL4: -16.772022 | AM4: 0 | AN4: 0 | AO4: 0 | AP4: 0 | AQ4: 0 | AR4: 0
A5: 2 | B5: MEWS Oriented Strand Board | C5: 650 | D5: 1880 | E5: 0.0994 | F5: 1.6e-14 | G5: 4.8884e-12 | H5: 1.5423 | I5: -4.4468 | J5: 0.10745 | K5: 1 | L5: 0.83636 | M5: 4.5881 | N5: -1.0827 | O5: 40.595 | P5: 0 | Q5: 0 | R5: 2 | S5: 0.92 | T5: -18.023 | U5: -34.413 | V5: 140.32 | W5: -285.57 | X5: 277.28 | Y5: -102.33 | Z5: 0 | AA5: 0.92 | AB5: 1.4 | AC5: -21.996232 | AD5: 0 | AE5: 0 | AF5: 0 | AG5: 0 | AH5: 0 | AI5: 0 | AJ5: 0 | AK5: 0 | AL5: 0 | AM5: 0 | AN5: 0 | AO5: 0 | AP5: 0 | AQ5: 0 | AR5: 0
A6: 3 | B6: MEWS Plywood | C6: 500 | D6: 1880 | E6: 0.0935 | F6: 8.5e-15 | G6: 2.6904e-11 | H6: 0.0031017 | I6: -4.53 | J6: 1.4008 | K6: 1 | L6: 0.87267 | M6: 2.3742 | N6: -1.3561 | O6: 38.492 | P6: 0 | Q6: 0 | R6: 2 | S6: 1.2 | T6: -18.117 | U6: -24.848 | V6: 75.351 | W6: -115.08 | X6: 84.348 | Y6: -23.595 | Z6: 0 | AA6: 1.2 | AB6: 1.6 | AC6: -21.996232 | AD6: 0 | AE6: 0 | AF6: 0 | AG6: 0 | AH6: 0 | AI6: 0 | AJ6: 0 | AK6: 0 | AL6: 0 | AM6: 0 | AN6: 0 | AO6: 0 | AP6: 0 | AQ6: 0 | AR6: 0
A7: 4 | B7: MEWS Building Membrane IA | C7: 360 | D7: 1250 | E7: 0.1 | F7: 1.1e-13 | G7: 2.5689e-13 | H7: 0.00033315 | I7: -0.1252 | J7: 0.95758 | K7: 1 | L7: 0 | M7: 0 | N7: 0 | O7: 0 | P7: 0 | Q7: 0 | R7: 0 | S7: 0 | T7: 11.512915 | U7: 0 | V7: 0 | W7: 0 | X7: 0 | Y7: 0 | Z7: 0 | AA7: 0 | AB7: 0 | AC7: 0 | AD7: 0 | AE7: 0 | AF7: 0 | AG7: 0 | AH7: 0 | AI7: 0 | AJ7: 0 | AK7: 0 | AL7: 0 | AM7: 0 | AN7: 0 | AO7: 0 | AP7: 0 | AQ7: 0 | AR7: 0
A8: 5 | B8: MEWS Building Membrane II | C8: 1000 | D8: 1250 | E8: 0.1 | F8: 2.2e-14 | G8: 8.243e-13 | H8: 0.020187 | I8: -2.5641 | J8: 1.3182 | K8: 1 | L8: 0 | M8: 0 | N8: 0 | O8: 0 | P8: 0 | Q8: 0 | R8: 0 | S8: 0 | T8: 11.512915 | U8: 0 | V8: 0 | W8: 0 | X8: 0 | Y8: 0 | Z8: 0 | AA8: 0 | AB8: 0 | AC8: 0 | AD8: 0 | AE8: 0 | AF8: 0 | AG8: 0 | AH8: 0 | AI8: 0 | AJ8: 0 | AK8: 0 | AL8: 0 | AM8: 0 | AN8: 0 | AO8: 0 | AP8: 0 | AQ8: 0 | AR8: 0
A9: 6 | B9: MEWS Building Membrane III | C9: 1010 | D9: 1250 | E9: 0.1 | F9: 1.2e-14 | G9: 1.2228e-12 | H9: 0.0328 | I9: -2.222 | J9: 1.0541 | K9: 1 | L9: 0 | M9: 0 | N9: 0 | O9: 0 | P9: 0 | Q9: 0 | R9: 0 | S9: 0 | T9: 11.512915 | U9: 0 | V9: 0 | W9: 0 | X9: 0 | Y9: 0 | Z9: 0 | AA9: 0 | AB9: 0 | AC9: 0 | AD9: 0 | AE9: 0 | AF9: 0 | AG9: 0 | AH9: 0 | AI9: 0 | AJ9: 0 | AK9: 0 | AL9: 0 | AM9: 0 | AN9: 0 | AO9: 0 | AP9: 0 | AQ9: 0 | AR9: 0
A10: 7 | B10: MEWS Building Membrane IVA | C10: 640 | D10: 1250 | E10: 0.1 | F10: 3.6e-14 | G10: 8.9e-13 | H10: 0 | I10: 0 | J10: 0 | K10: 1 | L10: 0 | M10: 0 | N10: 0 | O10: 0 | P10: 0 | Q10: 0 | R10: 0 | S10: 0 | T10: 11.512915 | U10: 0 | V10: 0 | W10: 0 | X10: 0 | Y10: 0 | Z10: 0 | AA10: 0 | AB10: 0 | AC10: 0 | AD10: 0 | AE10: 0 | AF10: 0 | AG10: 0 | AH10: 0 | AI10: 0 | AJ10: 0 | AK10: 0 | AL10: 0 | AM10: 0 | AN10: 0 | AO10: 0 | AP10: 0 | AQ10: 0 | AR10: 0
A11: 8 | B11: MEWS Building Membrane V A | C11: 810 | D11: 1250 | E11: 0.1 | F11: 2.2e-14 | G11: 2.1925e-12 | H11: 0.68619 | I11: -2.2596 | J11: 4.6009 | K11: 1 | L11: 0 | M11: 0 | N11: 0 | O11: 0 | P11: 0 | Q11: 0 | R11: 0 | S11: 0 | T11: 11.512915 | U11: 0 | V11: 0 | W11: 0 | X11: 0 | Y11: 0 | Z11: 0 | AA11: 0 | AB11: 0 | AC11: 0 | AD11: 0 | AE11: 0 | AF11: 0 | AG11: 0 | AH11: 0 | AI11: 0 | AJ11: 0 | AK11: 0 | AL11: 0 | AM11: 0 | AN11: 0 | AO11: 0 | AP11: 0 | AQ11: 0 | AR11: 0
A12: 9 | B12: MEWS Building Membrane V C | C12: 880 | D12: 1250 | E12: 0.1 | F12: 2.7e-15 | G12: 2.6194e-12 | H12: 0.83333 | I12: -3.5642 | J12: 6.6021 | K12: 1 | L12: 0 | M12: 0 | N12: 0 | O12: 0 | P12: 0 | Q12: 0 | R12: 0 | S12: 0 | T12: 11.512915 | U12: 0 | V12: 0 | W12: 0 | X12: 0 | Y12: 0 | Z12: 0 | AA12: 0 | AB12: 0 | AC12: 0 | AD12: 0 | AE12: 0 | AF12: 0 | AG12: 0 | AH12: 0 | AI12: 0 | AJ12: 0 | AK12: 0 | AL12: 0 | AM12: 0 | AN12: 0 | AO12: 0 | AP12: 0 | AQ12: 0 | AR12: 0
A13: 10 | B13: MEWS Building Membrane VI | C13: 1400 | D13: 1250 | E13: 0.1 | F13: 0 | G13: 2.4912e-13 | H13: 2.5029 | I13: -2.2913 | J13: 9.0327 | K13: 1 | L13: 0 | M13: 0 | N13: 0 | O13: 0 | P13: 0 | Q13: 0 | R13: 0 | S13: 0 | T13: 11.512915 | U13: 0 | V13: 0 | W13: 0 | X13: 0 | Y13: 0 | Z13: 0 | AA13: 0 | AB13: 0 | AC13: 0 | AD13: 0 | AE13: 0 | AF13: 0 | AG13: 0 | AH13: 0 | AI13: 0 | AJ13: 0 | AK13: 0 | AL13: 0 | AM13: 0 | AN13: 0 | AO13: 0 | AP13: 0 | AQ13: 0 | AR13: 0
A14: 11 | B14: MEWS Building Membrane VII | C14: 620 | D14: 1250 | E14: 0.1 | F14: 8.2e-17 | G14: 2.6e-13 | H14: 0 | I14: 0 | J14: 0 | K14: 1 | L14: 0 | M14: 0 | N14: 0 | O14: 0 | P14: 0 | Q14: 0 | R14: 0 | S14: 0 | T14: 11.512915 | U14: 0 | V14: 0 | W14: 0 | X14: 0 | Y14: 0 | Z14: 0 | AA14: 0 | AB14: 0 | AC14: 0 | AD14: 0 | AE14: 0 | AF14: 0 | AG14: 0 | AH14: 0 | AI14: 0 | AJ14: 0 | AK14: 0 | AL14: 0 | AM14: 0 | AN14: 0 | AO14: 0 | AP14: 0 | AQ14: 0 | AR14: 0
... A83: 80 | B83: ASHRAE Low-density Glassfibre Batt Insulation | C83: 32 | D83: 840 | E83: 0.043002 | F83: 3.5e-09 | G83: 1.7e-10 | H83: 0 | I83: 0 | J83: 0 | K83: 2 | L83: 0.027903 | M83: 0.64024 | N83: -1.5875 | O83: 7.1897 | P83: 87 | Q83: 0.022224101 | R83: 2 | S83: 0.022 | T83: -36.841361 | U83: 0 | V83: 0 | W83: 0 | X83: 0 | Y83: 0 | Z83: 0 | AA83: 0.023 | AB83: 87 | AC83: -18.420681 | AD83: 0 | AE83: 0 | AF83: 0 | AG83: 0 | AH83: 0 | AI83: 0 | AJ83: 0 | AK83: 0 | AL83: 0 | AM83: 0 | AN83: 0 | AO83: 0 | AP83: 0 | AQ83: 0 | AR83: 0

Sheet 湿気伝導率
A1: 湿気伝導率 | D1: Y = a·X^b · exp(c·(1 − X^d))
A2: No | B2: 材料名 | C2: a | D2: b | E2: c | F2: d | G2: 0 | H2: 0.02 | I2: 0.04 | J2: 0.06 | K2: 0.08 | L2: 0.1 | M2: 0.12 | N2: 0.14 | O2: 0.16 | P2: 0.18 | Q2: 0.2 | R2: 0.22 | S2: 0.24 | T2: 0.26 | U2: 0.28 | V2: 0.3 | W2: 0.32 | X2: 0.34 | Y2: 0.36 | Z2: 0.38 | AA2: 0.4 | AB2: 0.42 | AC2: 0.44 | AD2: 0.46 | AE2: 0.48 | AF2: 0.5 | AG2: 0.52 | AH2: 0.54 | AI2: 0.56 | AJ2: 0.58 | AK2: 0.6 | AL2: 0.62 | AM2: 0.64 | AN2: 0.66 | AO2: 0.68 | AP2: 0.7 | AQ2: 0.72 | AR2: 0.74 | AS2: 0.76 | AT2: 0.78 | AU2: 0.8 | AV2: 0.82 | AW2: 0.84 | AX2: 0.86 | AY2: 0.88 | AZ2: 0.9 | BA2: 0.92 | BB2: 0.94 | BC2: 0.96 | BD2: 0.961 | BE2: 0.962 | BF2: 0.963 | BG2: 0.964 | BH2: 0.965 | BI2: 0.966 | BJ2: 0.967 | BK2: 0.968 | BL2: 0.969 | BM2: 0.97 | BN2: 0.971 | BO2: 0.972 | BP2: 0.973 | BQ2: 0.974 | BR2: 0.975 | BS2: 0.976 | BT2: 0.977 | BU2: 0.978 | BV2: 0.979 | BW2: 0.98 | BX2: 0.981 | BY2: 0.982 | BZ2: 0.983 | CA2: 0.984 | CB2: 0.985 | CC2: 0.986 | CD2: 0.987 | CE2: 0.988 | CF2: 0.989 | CG2: 0.99 | CH2: 0.991 | CI2: 0.992 | CJ2: 0.993 | CK2: 0.994 | CL2: 0.995 | CM2: 0.996 | CN2: 0.997 | CO2: 0.998 | CP2: 0.999 | CQ2: 1
A3: 1 | B3: =データファイル用!$B4 -> MEWS Aerated Concrete | C3: =データファイル用!G4 -> 6.1555e-11 | D3: =データファイル用!H4 -> 0.04535 | E3: =データファイル用!I4 -> -1.7048 | F3: =データファイル用!J4 -> 1.2049 | G3: =$C3*IF(AND(G$2=0,$D3=0),1,G$2^$D3)*EXP($E3*(1-IF(AND(G$2=0,$F3=0),1,G$2^$F3))) -> 0 | H3: =$C3*IF(AND(H$2=0,$D3=0),1,H$2^$D3)*EXP($E3*(1-IF(AND(H$2=0,$F3=0),1,H$2^$F3))) -> 9.5164043e-12 | I3: =$C3*IF(AND(I$2=0,$D3=0),1,I$2^$D3)*EXP($E3*(1-IF(AND(I$2=0,$F3=0),1,I$2^$F3))) -> 1.0018327e-11 | J3: =$C3*IF(AND(J$2=0,$D3=0),1,J$2^$D3)*EXP($E3*(1-IF(AND(J$2=0,$F3=0),1,J$2^$F3))) -> 1.0433444e-11 | K3: =$C3*IF(AND(K$2=0,$D3=0),1,K$2^$D3)*EXP($E3*(1-IF(AND(K$2=0,$F3=0),1,K$2^$F3))) -> 1.0825166e-11 | L3: =$C3*IF(AND(L$2=0,$D3=0),1,L$2^$D3)*EXP($E3*(1-IF(AND(L$2=0,$F3=0),1,L$2^$F3))) -> 1.1212931e-11 | M3: =$C3*IF(AND(M$2=0,$D3=0),1,M$2^$D3)*EXP($E3*(1-IF(AND(M$2=0,$F3=0),1,M$2^$F3))) -> 1.1605346e-11 | N3: =$C3*IF(AND(N$2=0,$D3=0),1,N$2^$D3)*EXP($E3*(1-IF(AND(N$2=0,$F3=0),1,N$2^$F3))) -> 1.20071e-11 | ... CQ3: =$C3*IF(AND(CQ$2=0,$D3=0),1,CQ$2^$D3)*EXP($E3*(1-IF(AND(CQ$2=0,$F3=0),1,CQ$2^$F3))) -> 6.1555e-11
A4: 2 | B4: =データファイル用!$B5 -> MEWS Oriented Strand Board | C4: =データファイル用!G5 -> 4.8884e-12 | D4: =データファイル用!H5 -> 1.5423 | E4: =データファイル用!I5 -> -4.4468 | F4: =データファイル用!J5 -> 0.10745 | G4: =$C4*IF(AND(G$2=0,$D4=0),1,G$2^$D4)*EXP($E4*(1-IF(AND(G$2=0,$F4=0),1,G$2^$F4))) -> 0 | H4: =$C4*IF(AND(H$2=0,$D4=0),1,H$2^$D4)*EXP($E4*(1-IF(AND(H$2=0,$F4=0),1,H$2^$F4))) -> 2.5473402e-15 | I4: =$C4*IF(AND(I$2=0,$D4=0),1,I$2^$D4)*EXP($E4*(1-IF(AND(I$2=0,$F4=0),1,I$2^$F4))) -> 9.299209e-15 | J4: =$C4*IF(AND(J$2=0,$D4=0),1,J$2^$D4)*EXP($E4*(1-IF(AND(J$2=0,$F4=0),1,J$2^$F4))) -> 1.9993278e-14 | K4: =$C4*IF(AND(K$2=0,$D4=0),1,K$2^$D4)*EXP($E4*(1-IF(AND(K$2=0,$F4=0),1,K$2^$F4))) -> 3.4545293e-14 | L4: =$C4*IF(AND(L$2=0,$D4=0),1,L$2^$D4)*EXP($E4*(1-IF(AND(L$2=0,$F4=0),1,L$2^$F4))) -> 5.291497e-14 | M4: =$C4*IF(AND(M$2=0,$D4=0),1,M$2^$D4)*EXP($E4*(1-IF(AND(M$2=0,$F4=0),1,M$2^$F4))) -> 7.508136e-14 | N4: =$C4*IF(AND(N$2=0,$D4=0),1,N$2^$D4)*EXP($E4*(1-IF(AND(N$2=0,$F4=0),1,N$2^$F4))) -> 1.0103388e-13 | ... CQ4: =$C4*IF(AND(CQ$2=0,$D4=0),1,CQ$2^$D4)*EXP($E4*(1-IF(AND(CQ$2=0,$F4=0),1,CQ$2^$F4))) -> 4.8884e-12
A5: 3 | B5: =データファイル用!$B6 -> MEWS Plywood | C5: =データファイル用!G6 -> 2.6904e-11 | D5: =データファイル用!H6 -> 0.0031017 | E5: =データファイル用!I6 -> -4.53 | F5: =データファイル用!J6 -> 1.4008 | G5: =$C5*IF(AND(G$2=0,$D5=0),1,G$2^$D5)*EXP($E5*(1-IF(AND(G$2=0,$F5=0),1,G$2^$F5))) -> 0 | H5: =$C5*IF(AND(H$2=0,$D5=0),1,H$2^$D5)*EXP($E5*(1-IF(AND(H$2=0,$F5=0),1,H$2^$F5))) -> 2.9200885e-13 | I5: =$C5*IF(AND(I$2=0,$D5=0),1,I$2^$D5)*EXP($E5*(1-IF(AND(I$2=0,$F5=0),1,I$2^$F5))) -> 3.0184664e-13 | J5: =$C5*IF(AND(J$2=0,$D5=0),1,J$2^$D5)*EXP($E5*(1-IF(AND(J$2=0,$F5=0),1,J$2^$F5))) -> 3.139752e-13 | K5: =$C5*IF(AND(K$2=0,$D5=0),1,K$2^$D5)*EXP($E5*(1-IF(AND(K$2=0,$F5=0),1,K$2^$F5))) -> 3.2828572e-13 | L5: =$C5*IF(AND(L$2=0,$D5=0),1,L$2^$D5)*EXP($E5*(1-IF(AND(L$2=0,$F5=0),1,L$2^$F5))) -> 3.4477739e-13 | M5: =$C5*IF(AND(M$2=0,$D5=0),1,M$2^$D5)*EXP($E5*(1-IF(AND(M$2=0,$F5=0),1,M$2^$F5))) -> 3.6352304e-13 | N5: =$C5*IF(AND(N$2=0,$D5=0),1,N$2^$D5)*EXP($E5*(1-IF(AND(N$2=0,$F5=0),1,N$2^$F5))) -> 3.8464905e-13 | ... CQ5: =$C5*IF(AND(CQ$2=0,$D5=0),1,CQ$2^$D5)*EXP($E5*(1-IF(AND(CQ$2=0,$F5=0),1,CQ$2^$F5))) -> 2.6904e-11
A6: 4 | B6: =データファイル用!$B7 -> MEWS Building Membrane IA | C6: =データファイル用!G7 -> 2.5689e-13 | D6: =データファイル用!H7 -> 0.00033315 | E6: =データファイル用!I7 -> -0.1252 | F6: =データファイル用!J7 -> 0.95758 | G6: =$C6*IF(AND(G$2=0,$D6=0),1,G$2^$D6)*EXP($E6*(1-IF(AND(G$2=0,$F6=0),1,G$2^$F6))) -> 0 | H6: =$C6*IF(AND(H$2=0,$D6=0),1,H$2^$D6)*EXP($E6*(1-IF(AND(H$2=0,$F6=0),1,H$2^$F6))) -> 2.270342e-13 | I6: =$C6*IF(AND(I$2=0,$D6=0),1,I$2^$D6)*EXP($E6*(1-IF(AND(I$2=0,$F6=0),1,I$2^$F6))) -> 2.2771989e-13 | J6: =$C6*IF(AND(J$2=0,$D6=0),1,J$2^$D6)*EXP($E6*(1-IF(AND(J$2=0,$F6=0),1,J$2^$F6))) -> 2.2837178e-13 | K6: =$C6*IF(AND(K$2=0,$D6=0),1,K$2^$D6)*EXP($E6*(1-IF(AND(K$2=0,$F6=0),1,K$2^$F6))) -> 2.2900762e-13 | L6: =$C6*IF(AND(L$2=0,$D6=0),1,L$2^$D6)*EXP($E6*(1-IF(AND(L$2=0,$F6=0),1,L$2^$F6))) -> 2.2963371e-13 | M6: =$C6*IF(AND(M$2=0,$D6=0),1,M$2^$D6)*EXP($E6*(1-IF(AND(M$2=0,$F6=0),1,M$2^$F6))) -> 2.3025319e-13 | N6: =$C6*IF(AND(N$2=0,$D6=0),1,N$2^$D6)*EXP($E6*(1-IF(AND(N$2=0,$F6=0),1,N$2^$F6))) -> 2.3086787e-13 | ... CQ6: =$C6*IF(AND(CQ$2=0,$D6=0),1,CQ$2^$D6)*EXP($E6*(1-IF(AND(CQ$2=0,$F6=0),1,CQ$2^$F6))) -> 2.5689e-13
A7: 5 | B7: =データファイル用!$B8 -> MEWS Building Membrane II | C7: =データファイル用!G8 -> 8.243e-13 | D7: =データファイル用!H8 -> 0.020187 | E7: =データファイル用!I8 -> -2.5641 | F7: =データファイル用!J8 -> 1.3182 | G7: =$C7*IF(AND(G$2=0,$D7=0),1,G$2^$D7)*EXP($E7*(1-IF(AND(G$2=0,$F7=0),1,G$2^$F7))) -> 0 | H7: =$C7*IF(AND(H$2=0,$D7=0),1,H$2^$D7)*EXP($E7*(1-IF(AND(H$2=0,$F7=0),1,H$2^$F7))) -> 5.9515191e-14 | I7: =$C7*IF(AND(I$2=0,$D7=0),1,I$2^$D7)*EXP($E7*(1-IF(AND(I$2=0,$F7=0),1,I$2^$F7))) -> 6.1699908e-14 | J7: =$C7*IF(AND(J$2=0,$D7=0),1,J$2^$D7)*EXP($E7*(1-IF(AND(J$2=0,$F7=0),1,J$2^$F7))) -> 6.3846935e-14 | K7: =$C7*IF(AND(K$2=0,$D7=0),1,K$2^$D7)*EXP($E7*(1-IF(AND(K$2=0,$F7=0),1,K$2^$F7))) -> 6.610725e-14 | L7: =$C7*IF(AND(L$2=0,$D7=0),1,L$2^$D7)*EXP($E7*(1-IF(AND(L$2=0,$F7=0),1,L$2^$F7))) -> 6.8524237e-14 | M7: =$C7*IF(AND(M$2=0,$D7=0),1,M$2^$D7)*EXP($E7*(1-IF(AND(M$2=0,$F7=0),1,M$2^$F7))) -> 7.1118549e-14 | N7: =$C7*IF(AND(N$2=0,$D7=0),1,N$2^$D7)*EXP($E7*(1-IF(AND(N$2=0,$F7=0),1,N$2^$F7))) -> 7.39043e-14 | ... CQ7: =$C7*IF(AND(CQ$2=0,$D7=0),1,CQ$2^$D7)*EXP($E7*(1-IF(AND(CQ$2=0,$F7=0),1,CQ$2^$F7))) -> 8.243e-13
A8: 6 | B8: =データファイル用!$B9 -> MEWS Building Membrane III | C8: =データファイル用!G9 -> 1.2228e-12 | D8: =データファイル用!H9 -> 0.0328 | E8: =データファイル用!I9 -> -2.222 | F8: =データファイル用!J9 -> 1.0541 | G8: =$C8*IF(AND(G$2=0,$D8=0),1,G$2^$D8)*EXP($E8*(1-IF(AND(G$2=0,$F8=0),1,G$2^$F8))) -> 0 | H8: =$C8*IF(AND(H$2=0,$D8=0),1,H$2^$D8)*EXP($E8*(1-IF(AND(H$2=0,$F8=0),1,H$2^$F8))) -> 1.2084969e-13 | I8: =$C8*IF(AND(I$2=0,$D8=0),1,I$2^$D8)*EXP($E8*(1-IF(AND(I$2=0,$F8=0),1,I$2^$F8))) -> 1.2850843e-13 | J8: =$C8*IF(AND(J$2=0,$D8=0),1,J$2^$D8)*EXP($E8*(1-IF(AND(J$2=0,$F8=0),1,J$2^$F8))) -> 1.3551949e-13 | K8: =$C8*IF(AND(K$2=0,$D8=0),1,K$2^$D8)*EXP($E8*(1-IF(AND(K$2=0,$F8=0),1,K$2^$F8))) -> 1.4246718e-13 | L8: =$C8*IF(AND(L$2=0,$D8=0),1,L$2^$D8)*EXP($E8*(1-IF(AND(L$2=0,$F8=0),1,L$2^$F8))) -> 1.4953777e-13 | M8: =$C8*IF(AND(M$2=0,$D8=0),1,M$2^$D8)*EXP($E8*(1-IF(AND(M$2=0,$F8=0),1,M$2^$F8))) -> 1.5681984e-13 | N8: =$C8*IF(AND(N$2=0,$D8=0),1,N$2^$D8)*EXP($E8*(1-IF(AND(N$2=0,$F8=0),1,N$2^$F8))) -> 1.643668e-13 | ... CQ8: =$C8*IF(AND(CQ$2=0,$D8=0),1,CQ$2^$D8)*EXP($E8*(1-IF(AND(CQ$2=0,$F8=0),1,CQ$2^$F8))) -> 1.2228e-12
A9: 7 | B9: =データファイル用!$B10 -> MEWS Building Membrane IVA | C9: =データファイル用!G10 -> 8.9e-13 | D9: =データファイル用!H10 -> 0 | E9: =データファイル用!I10 -> 0 | F9: =データファイル用!J10 -> 0 | G9: =$C9*IF(AND(G$2=0,$D9=0),1,G$2^$D9)*EXP($E9*(1-IF(AND(G$2=0,$F9=0),1,G$2^$F9))) -> 8.9e-13 | H9: =$C9*IF(AND(H$2=0,$D9=0),1,H$2^$D9)*EXP($E9*(1-IF(AND(H$2=0,$F9=0),1,H$2^$F9))) -> 8.9e-13 | I9: =$C9*IF(AND(I$2=0,$D9=0),1,I$2^$D9)*EXP($E9*(1-IF(AND(I$2=0,$F9=0),1,I$2^$F9))) -> 8.9e-13 | J9: =$C9*IF(AND(J$2=0,$D9=0),1,J$2^$D9)*EXP($E9*(1-IF(AND(J$2=0,$F9=0),1,J$2^$F9))) -> 8.9e-13 | K9: =$C9*IF(AND(K$2=0,$D9=0),1,K$2^$D9)*EXP($E9*(1-IF(AND(K$2=0,$F9=0),1,K$2^$F9))) -> 8.9e-13 | L9: =$C9*IF(AND(L$2=0,$D9=0),1,L$2^$D9)*EXP($E9*(1-IF(AND(L$2=0,$F9=0),1,L$2^$F9))) -> 8.9e-13 | M9: =$C9*IF(AND(M$2=0,$D9=0),1,M$2^$D9)*EXP($E9*(1-IF(AND(M$2=0,$F9=0),1,M$2^$F9))) -> 8.9e-13 | N9: =$C9*IF(AND(N$2=0,$D9=0),1,N$2^$D9)*EXP($E9*(1-IF(AND(N$2=0,$F9=0),1,N$2^$F9))) -> 8.9e-13 | ... CQ9: =$C9*IF(AND(CQ$2=0,$D9=0),1,CQ$2^$D9)*EXP($E9*(1-IF(AND(CQ$2=0,$F9=0),1,CQ$2^$F9))) -> 8.9e-13
A10: 8 | B10: =データファイル用!$B11 -> MEWS Building Membrane V A | C10: =データファイル用!G11 -> 2.1925e-12 | D10: =データファイル用!H11 -> 0.68619 | E10: =データファイル用!I11 -> -2.2596 | F10: =データファイル用!J11 -> 4.6009 | G10: =$C10*IF(AND(G$2=0,$D10=0),1,G$2^$D10)*EXP($E10*(1-IF(AND(G$2=0,$F10=0),1,G$2^$F10))) -> 0 | H10: =$C10*IF(AND(H$2=0,$D10=0),1,H$2^$D10)*EXP($E10*(1-IF(AND(H$2=0,$F10=0),1,H$2^$F10))) -> 1.5623977e-14 | I10: =$C10*IF(AND(I$2=0,$D10=0),1,I$2^$D10)*EXP($E10*(1-IF(AND(I$2=0,$F10=0),1,I$2^$F10))) -> 2.5139446e-14 | J10: =$C10*IF(AND(J$2=0,$D10=0),1,J$2^$D10)*EXP($E10*(1-IF(AND(J$2=0,$F10=0),1,J$2^$F10))) -> 3.3203949e-14 | K10: =$C10*IF(AND(K$2=0,$D10=0),1,K$2^$D10)*EXP($E10*(1-IF(AND(K$2=0,$F10=0),1,K$2^$F10))) -> 4.0450875e-14 | L10: =$C10*IF(AND(L$2=0,$D10=0),1,L$2^$D10)*EXP($E10*(1-IF(AND(L$2=0,$F10=0),1,L$2^$F10))) -> 4.7145733e-14 | M10: =$C10*IF(AND(M$2=0,$D10=0),1,M$2^$D10)*EXP($E10*(1-IF(AND(M$2=0,$F10=0),1,M$2^$F10))) -> 5.3432819e-14 | N10: =$C10*IF(AND(N$2=0,$D10=0),1,N$2^$D10)*EXP($E10*(1-IF(AND(N$2=0,$F10=0),1,N$2^$F10))) -> 5.9402546e-14 | ... CQ10: =$C10*IF(AND(CQ$2=0,$D10=0),1,CQ$2^$D10)*EXP($E10*(1-IF(AND(CQ$2=0,$F10=0),1,CQ$2^$F10))) -> 2.1925e-12
A11: 9 | B11: =データファイル用!$B12 -> MEWS Building Membrane V C | C11: =データファイル用!G12 -> 2.6194e-12 | D11: =データファイル用!H12 -> 0.83333 | E11: =データファイル用!I12 -> -3.5642 | F11: =データファイル用!J12 -> 6.6021 | G11: =$C11*IF(AND(G$2=0,$D11=0),1,G$2^$D11)*EXP($E11*(1-IF(AND(G$2=0,$F11=0),1,G$2^$F11))) -> 0 | H11: =$C11*IF(AND(H$2=0,$D11=0),1,H$2^$D11)*EXP($E11*(1-IF(AND(H$2=0,$F11=0),1,H$2^$F11))) -> 2.847651e-15 | I11: =$C11*IF(AND(I$2=0,$D11=0),1,I$2^$D11)*EXP($E11*(1-IF(AND(I$2=0,$F11=0),1,I$2^$F11))) -> 5.0739255e-15 | J11: =$C11*IF(AND(J$2=0,$D11=0),1,J$2^$D11)*EXP($E11*(1-IF(AND(J$2=0,$F11=0),1,J$2^$F11))) -> 7.1135473e-15 | K11: =$C11*IF(AND(K$2=0,$D11=0),1,K$2^$D11)*EXP($E11*(1-IF(AND(K$2=0,$F11=0),1,K$2^$F11))) -> 9.0406883e-15 | L11: =$C11*IF(AND(L$2=0,$D11=0),1,L$2^$D11)*EXP($E11*(1-IF(AND(L$2=0,$F11=0),1,L$2^$F11))) -> 1.0888293e-14 | M11: =$C11*IF(AND(M$2=0,$D11=0),1,M$2^$D11)*EXP($E11*(1-IF(AND(M$2=0,$F11=0),1,M$2^$F11))) -> 1.2674908e-14 | N11: =$C11*IF(AND(N$2=0,$D11=0),1,N$2^$D11)*EXP($E11*(1-IF(AND(N$2=0,$F11=0),1,N$2^$F11))) -> 1.4412386e-14 | ... CQ11: =$C11*IF(AND(CQ$2=0,$D11=0),1,CQ$2^$D11)*EXP($E11*(1-IF(AND(CQ$2=0,$F11=0),1,CQ$2^$F11))) -> 2.6194e-12
A12: 10 | B12: =データファイル用!$B13 -> MEWS Building Membrane VI | C12: =データファイル用!G13 -> 2.4912e-13 | D12: =データファイル用!H13 -> 2.5029 | E12: =データファイル用!I13 -> -2.2913 | F12: =データファイル用!J13 -> 9.0327 | G12: =$C12*IF(AND(G$2=0,$D12=0),1,G$2^$D12)*EXP($E12*(1-IF(AND(G$2=0,$F12=0),1,G$2^$F12))) -> 0 | H12: =$C12*IF(AND(H$2=0,$D12=0),1,H$2^$D12)*EXP($E12*(1-IF(AND(H$2=0,$F12=0),1,H$2^$F12))) -> 1.4091513e-18 | I12: =$C12*IF(AND(I$2=0,$D12=0),1,I$2^$D12)*EXP($E12*(1-IF(AND(I$2=0,$F12=0),1,I$2^$F12))) -> 7.9874031e-18 | J12: =$C12*IF(AND(J$2=0,$D12=0),1,J$2^$D12)*EXP($E12*(1-IF(AND(J$2=0,$F12=0),1,J$2^$F12))) -> 2.2036591e-17 | K12: =$C12*IF(AND(K$2=0,$D12=0),1,K$2^$D12)*EXP($E12*(1-IF(AND(K$2=0,$F12=0),1,K$2^$F12))) -> 4.5274491e-17 | L12: =$C12*IF(AND(L$2=0,$D12=0),1,L$2^$D12)*EXP($E12*(1-IF(AND(L$2=0,$F12=0),1,L$2^$F12))) -> 7.9142479e-17 | M12: =$C12*IF(AND(M$2=0,$D12=0),1,M$2^$D12)*EXP($E12*(1-IF(AND(M$2=0,$F12=0),1,M$2^$F12))) -> 1.2490862e-16 | N12: =$C12*IF(AND(N$2=0,$D12=0),1,N$2^$D12)*EXP($E12*(1-IF(AND(N$2=0,$F12=0),1,N$2^$F12))) -> 1.8371877e-16 | ... CQ12: =$C12*IF(AND(CQ$2=0,$D12=0),1,CQ$2^$D12)*EXP($E12*(1-IF(AND(CQ$2=0,$F12=0),1,CQ$2^$F12))) -> 2.4912e-13
A13: 11 | B13: =データファイル用!$B14 -> MEWS Building Membrane VII | C13: =データファイル用!G14 -> 2.6e-13 | D13: =データファイル用!H14 -> 0 | E13: =データファイル用!I14 -> 0 | F13: =データファイル用!J14 -> 0 | G13: =$C13*IF(AND(G$2=0,$D13=0),1,G$2^$D13)*EXP($E13*(1-IF(AND(G$2=0,$F13=0),1,G$2^$F13))) -> 2.6e-13 | H13: =$C13*IF(AND(H$2=0,$D13=0),1,H$2^$D13)*EXP($E13*(1-IF(AND(H$2=0,$F13=0),1,H$2^$F13))) -> 2.6e-13 | I13: =$C13*IF(AND(I$2=0,$D13=0),1,I$2^$D13)*EXP($E13*(1-IF(AND(I$2=0,$F13=0),1,I$2^$F13))) -> 2.6e-13 | J13: =$C13*IF(AND(J$2=0,$D13=0),1,J$2^$D13)*EXP($E13*(1-IF(AND(J$2=0,$F13=0),1,J$2^$F13))) -> 2.6e-13 | K13: =$C13*IF(AND(K$2=0,$D13=0),1,K$2^$D13)*EXP($E13*(1-IF(AND(K$2=0,$F13=0),1,K$2^$F13))) -> 2.6e-13 | L13: =$C13*IF(AND(L$2=0,$D13=0),1,L$2^$D13)*EXP($E13*(1-IF(AND(L$2=0,$F13=0),1,L$2^$F13))) -> 2.6e-13 | M13: =$C13*IF(AND(M$2=0,$D13=0),1,M$2^$D13)*EXP($E13*(1-IF(AND(M$2=0,$F13=0),1,M$2^$F13))) -> 2.6e-13 | N13: =$C13*IF(AND(N$2=0,$D13=0),1,N$2^$D13)*EXP($E13*(1-IF(AND(N$2=0,$F13=0),1,N$2^$F13))) -> 2.6e-13 | ... CQ13: =$C13*IF(AND(CQ$2=0,$D13=0),1,CQ$2^$D13)*EXP($E13*(1-IF(AND(CQ$2=0,$F13=0),1,CQ$2^$F13))) -> 2.6e-13
A14: 12 | B14: =データファイル用!$B15 -> MEWS Building Membrane VIII | C14: =データファイル用!G15 -> 1.6e-13 | D14: =データファイル用!H15 -> 0 | E14: =データファイル用!I15 -> 0 | F14: =データファイル用!J15 -> 0 | G14: =$C14*IF(AND(G$2=0,$D14=0),1,G$2^$D14)*EXP($E14*(1-IF(AND(G$2=0,$F14=0),1,G$2^$F14))) -> 1.6e-13 | H14: =$C14*IF(AND(H$2=0,$D14=0),1,H$2^$D14)*EXP($E14*(1-IF(AND(H$2=0,$F14=0),1,H$2^$F14))) -> 1.6e-13 | I14: =$C14*IF(AND(I$2=0,$D14=0),1,I$2^$D14)*EXP($E14*(1-IF(AND(I$2=0,$F14=0),1,I$2^$F14))) -> 1.6e-13 | J14: =$C14*IF(AND(J$2=0,$D14=0),1,J$2^$D14)*EXP($E14*(1-IF(AND(J$2=0,$F14=0),1,J$2^$F14))) -> 1.6e-13 | K14: =$C14*IF(AND(K$2=0,$D14=0),1,K$2^$D14)*EXP($E14*(1-IF(AND(K$2=0,$F14=0),1,K$2^$F14))) -> 1.6e-13 | L14: =$C14*IF(AND(L$2=0,$D14=0),1,L$2^$D14)*EXP($E14*(1-IF(AND(L$2=0,$F14=0),1,L$2^$F14))) -> 1.6e-13 | M14: =$C14*IF(AND(M$2=0,$D14=0),1,M$2^$D14)*EXP($E14*(1-IF(AND(M$2=0,$F14=0),1,M$2^$F14))) -> 1.6e-13 | N14: =$C14*IF(AND(N$2=0,$D14=0),1,N$2^$D14)*EXP($E14*(1-IF(AND(N$2=0,$F14=0),1,N$2^$F14))) -> 1.6e-13 | ... CQ14: =$C14*IF(AND(CQ$2=0,$D14=0),1,CQ$2^$D14)*EXP($E14*(1-IF(AND(CQ$2=0,$F14=0),1,CQ$2^$F14))) -> 1.6e-13
... A82: 80 | B82: =データファイル用!$B83 -> ASHRAE Low-density Glassfibre Batt Insulation | C82: =データファイル用!G83 -> 1.7e-10 | D82: =データファイル用!H83 -> 0 | E82: =データファイル用!I83 -> 0 | F82: =データファイル用!J83 -> 0 | G82: =$C82*IF(AND(G$2=0,$D82=0),1,G$2^$D82)*EXP($E82*(1-IF(AND(G$2=0,$F82=0),1,G$2^$F82))) -> 1.7e-10 | H82: =$C82*IF(AND(H$2=0,$D82=0),1,H$2^$D82)*EXP($E82*(1-IF(AND(H$2=0,$F82=0),1,H$2^$F82))) -> 1.7e-10 | I82: =$C82*IF(AND(I$2=0,$D82=0),1,I$2^$D82)*EXP($E82*(1-IF(AND(I$2=0,$F82=0),1,I$2^$F82))) -> 1.7e-10 | J82: =$C82*IF(AND(J$2=0,$D82=0),1,J$2^$D82)*EXP($E82*(1-IF(AND(J$2=0,$F82=0),1,J$2^$F82))) -> 1.7e-10 | K82: =$C82*IF(AND(K$2=0,$D82=0),1,K$2^$D82)*EXP($E82*(1-IF(AND(K$2=0,$F82=0),1,K$2^$F82))) -> 1.7e-10 | L82: =$C82*IF(AND(L$2=0,$D82=0),1,L$2^$D82)*EXP($E82*(1-IF(AND(L$2=0,$F82=0),1,L$2^$F82))) -> 1.7e-10 | M82: =$C82*IF(AND(M$2=0,$D82=0),1,M$2^$D82)*EXP($E82*(1-IF(AND(M$2=0,$F82=0),1,M$2^$F82))) -> 1.7e-10 | N82: =$C82*IF(AND(N$2=0,$D82=0),1,N$2^$D82)*EXP($E82*(1-IF(AND(N$2=0,$F82=0),1,N$2^$F82))) -> 1.7e-10 | ... CQ82: =$C82*IF(AND(CQ$2=0,$D82=0),1,CQ$2^$D82)*EXP($E82*(1-IF(AND(CQ$2=0,$F82=0),1,CQ$2^$F82))) -> 1.7e-10
A83: グラフ比較用選択(ドロップダウンで材料を選択)
A84: 選択No | B84: 材料名(表示)
A85: 1 | B85: {=INDEX($B$3:$B$82,A85)} -> MEWS Aerated Concrete | C85: {=INDEX(C$3:C$82,$A85)} -> 6.1555e-11 | D85: {=INDEX(D$3:D$82,$A85)} -> 0.04535 | E85: {=INDEX(E$3:E$82,$A85)} -> -1.7048 | F85: {=INDEX(F$3:F$82,$A85)} -> 1.2049 | G85: =$C85*IF(AND(G$2=0,$D85=0),1,G$2^$D85)*EXP($E85*(1-IF(AND(G$2=0,$F85=0),1,G$2^$F85))) -> 0 | H85: =$C85*IF(AND(H$2=0,$D85=0),1,H$2^$D85)*EXP($E85*(1-IF(AND(H$2=0,$F85=0),1,H$2^$F85))) -> 9.5164043e-12 | I85: =$C85*IF(AND(I$2=0,$D85=0),1,I$2^$D85)*EXP($E85*(1-IF(AND(I$2=0,$F85=0),1,I$2^$F85))) -> 1.0018327e-11 | J85: =$C85*IF(AND(J$2=0,$D85=0),1,J$2^$D85)*EXP($E85*(1-IF(AND(J$2=0,$F85=0),1,J$2^$F85))) -> 1.0433444e-11 | K85: =$C85*IF(AND(K$2=0,$D85=0),1,K$2^$D85)*EXP($E85*(1-IF(AND(K$2=0,$F85=0),1,K$2^$F85))) -> 1.0825166e-11 | L85: =$C85*IF(AND(L$2=0,$D85=0),1,L$2^$D85)*EXP($E85*(1-IF(AND(L$2=0,$F85=0),1,L$2^$F85))) -> 1.1212931e-11 | M85: =$C85*IF(AND(M$2=0,$D85=0),1,M$2^$D85)*EXP($E85*(1-IF(AND(M$2=0,$F85=0),1,M$2^$F85))) -> 1.1605346e-11 | N85: =$C85*IF(AND(N$2=0,$D85=0),1,N$2^$D85)*EXP($E85*(1-IF(AND(N$2=0,$F85=0),1,N$2^$F85))) -> 1.20071e-11 | ... CQ85: =$C85*IF(AND(CQ$2=0,$D85=0),1,CQ$2^$D85)*EXP($E85*(1-IF(AND(CQ$2=0,$F85=0),1,CQ$2^$F85))) -> 6.1555e-11
A86: 61 | B86: {=INDEX($B$3:$B$82,A86)} -> ASHRAE Lime Stone | C86: {=INDEX(C$3:C$82,$A86)} -> 1.5819e-12 | D86: {=INDEX(D$3:D$82,$A86)} -> 0.0038359 | E86: {=INDEX(E$3:E$82,$A86)} -> -4.7902 | F86: {=INDEX(F$3:F$82,$A86)} -> 1.7801 | G86: =$C86*IF(AND(G$2=0,$D86=0),1,G$2^$D86)*EXP($E86*(1-IF(AND(G$2=0,$F86=0),1,G$2^$F86))) -> 0 | H86: =$C86*IF(AND(H$2=0,$D86=0),1,H$2^$D86)*EXP($E86*(1-IF(AND(H$2=0,$F86=0),1,H$2^$F86))) -> 1.3009827e-14 | I86: =$C86*IF(AND(I$2=0,$D86=0),1,I$2^$D86)*EXP($E86*(1-IF(AND(I$2=0,$F86=0),1,I$2^$F86))) -> 1.3189091e-14 | J86: =$C86*IF(AND(J$2=0,$D86=0),1,J$2^$D86)*EXP($E86*(1-IF(AND(J$2=0,$F86=0),1,J$2^$F86))) -> 1.3428832e-14 | K86: =$C86*IF(AND(K$2=0,$D86=0),1,K$2^$D86)*EXP($E86*(1-IF(AND(K$2=0,$F86=0),1,K$2^$F86))) -> 1.3734603e-14 | L86: =$C86*IF(AND(L$2=0,$D86=0),1,L$2^$D86)*EXP($E86*(1-IF(AND(L$2=0,$F86=0),1,L$2^$F86))) -> 1.4109223e-14 | M86: =$C86*IF(AND(M$2=0,$D86=0),1,M$2^$D86)*EXP($E86*(1-IF(AND(M$2=0,$F86=0),1,M$2^$F86))) -> 1.4555968e-14 | N86: =$C86*IF(AND(N$2=0,$D86=0),1,N$2^$D86)*EXP($E86*(1-IF(AND(N$2=0,$F86=0),1,N$2^$F86))) -> 1.5079095e-14 | ... CQ86: =$C86*IF(AND(CQ$2=0,$D86=0),1,CQ$2^$D86)*EXP($E86*(1-IF(AND(CQ$2=0,$F86=0),1,CQ$2^$F86))) -> 1.5819e-12
A87: 43 | B87: {=INDEX($B$3:$B$82,A87)} -> ASHRAE OSB -1 | C87: {=INDEX(C$3:C$82,$A87)} -> 3.3724e-12 | D87: {=INDEX(D$3:D$82,$A87)} -> 1.8546 | E87: {=INDEX(E$3:E$82,$A87)} -> -0.062945 | F87: {=INDEX(F$3:F$82,$A87)} -> 1.2563 | G87: =$C87*IF(AND(G$2=0,$D87=0),1,G$2^$D87)*EXP($E87*(1-IF(AND(G$2=0,$F87=0),1,G$2^$F87))) -> 0 | H87: =$C87*IF(AND(H$2=0,$D87=0),1,H$2^$D87)*EXP($E87*(1-IF(AND(H$2=0,$F87=0),1,H$2^$F87))) -> 2.2381709e-15 | I87: =$C87*IF(AND(I$2=0,$D87=0),1,I$2^$D87)*EXP($E87*(1-IF(AND(I$2=0,$F87=0),1,I$2^$F87))) -> 8.099572e-15 | J87: =$C87*IF(AND(J$2=0,$D87=0),1,J$2^$D87)*EXP($E87*(1-IF(AND(J$2=0,$F87=0),1,J$2^$F87))) -> 1.71933e-14 | K87: =$C87*IF(AND(K$2=0,$D87=0),1,K$2^$D87)*EXP($E87*(1-IF(AND(K$2=0,$F87=0),1,K$2^$F87))) -> 2.9337143e-14 | L87: =$C87*IF(AND(L$2=0,$D87=0),1,L$2^$D87)*EXP($E87*(1-IF(AND(L$2=0,$F87=0),1,L$2^$F87))) -> 4.4413759e-14 | M87: =$C87*IF(AND(M$2=0,$D87=0),1,M$2^$D87)*EXP($E87*(1-IF(AND(M$2=0,$F87=0),1,M$2^$F87))) -> 6.2338603e-14 | N87: =$C87*IF(AND(N$2=0,$D87=0),1,N$2^$D87)*EXP($E87*(1-IF(AND(N$2=0,$F87=0),1,N$2^$F87))) -> 8.3046947e-14 | ... CQ87: =$C87*IF(AND(CQ$2=0,$D87=0),1,CQ$2^$D87)*EXP($E87*(1-IF(AND(CQ$2=0,$F87=0),1,CQ$2^$F87))) -> 3.3724e-12
A88: 61 | B88: {=INDEX($B$3:$B$82,A88)} -> ASHRAE Lime Stone | C88: {=INDEX(C$3:C$82,$A88)} -> 1.5819e-12 | D88: {=INDEX(D$3:D$82,$A88)} -> 0.0038359 | E88: {=INDEX(E$3:E$82,$A88)} -> -4.7902 | F88: {=INDEX(F$3:F$82,$A88)} -> 1.7801 | G88: =$C88*IF(AND(G$2=0,$D88=0),1,G$2^$D88)*EXP($E88*(1-IF(AND(G$2=0,$F88=0),1,G$2^$F88))) -> 0 | H88: =$C88*IF(AND(H$2=0,$D88=0),1,H$2^$D88)*EXP($E88*(1-IF(AND(H$2=0,$F88=0),1,H$2^$F88))) -> 1.3009827e-14 | I88: =$C88*IF(AND(I$2=0,$D88=0),1,I$2^$D88)*EXP($E88*(1-IF(AND(I$2=0,$F88=0),1,I$2^$F88))) -> 1.3189091e-14 | J88: =$C88*IF(AND(J$2=0,$D88=0),1,J$2^$D88)*EXP($E88*(1-IF(AND(J$2=0,$F88=0),1,J$2^$F88))) -> 1.3428832e-14 | K88: =$C88*IF(AND(K$2=0,$D88=0),1,K$2^$D88)*EXP($E88*(1-IF(AND(K$2=0,$F88=0),1,K$2^$F88))) -> 1.3734603e-14 | L88: =$C88*IF(AND(L$2=0,$D88=0),1,L$2^$D88)*EXP($E88*(1-IF(AND(L$2=0,$F88=0),1,L$2^$F88))) -> 1.4109223e-14 | M88: =$C88*IF(AND(M$2=0,$D88=0),1,M$2^$D88)*EXP($E88*(1-IF(AND(M$2=0,$F88=0),1,M$2^$F88))) -> 1.4555968e-14 | N88: =$C88*IF(AND(N$2=0,$D88=0),1,N$2^$D88)*EXP($E88*(1-IF(AND(N$2=0,$F88=0),1,N$2^$F88))) -> 1.5079095e-14 | ... CQ88: =$C88*IF(AND(CQ$2=0,$D88=0),1,CQ$2^$D88)*EXP($E88*(1-IF(AND(CQ$2=0,$F88=0),1,CQ$2^$F88))) -> 1.5819e-12
A89: 75 | B89: {=INDEX($B$3:$B$82,A89)} -> ASHRAE Vinyl Wallpaper | C89: {=INDEX(C$3:C$82,$A89)} -> 1.1383e-13 | D89: {=INDEX(D$3:D$82,$A89)} -> 0.009708 | E89: {=INDEX(E$3:E$82,$A89)} -> -2.1327 | F89: {=INDEX(F$3:F$82,$A89)} -> 0.86874 | G89: =$C89*IF(AND(G$2=0,$D89=0),1,G$2^$D89)*EXP($E89*(1-IF(AND(G$2=0,$F89=0),1,G$2^$F89))) -> 0 | H89: =$C89*IF(AND(H$2=0,$D89=0),1,H$2^$D89)*EXP($E89*(1-IF(AND(H$2=0,$F89=0),1,H$2^$F89))) -> 1.3947608e-14 | I89: =$C89*IF(AND(I$2=0,$D89=0),1,I$2^$D89)*EXP($E89*(1-IF(AND(I$2=0,$F89=0),1,I$2^$F89))) -> 1.4893413e-14 | J89: =$C89*IF(AND(J$2=0,$D89=0),1,J$2^$D89)*EXP($E89*(1-IF(AND(J$2=0,$F89=0),1,J$2^$F89))) -> 1.5796948e-14 | K89: =$C89*IF(AND(K$2=0,$D89=0),1,K$2^$D89)*EXP($E89*(1-IF(AND(K$2=0,$F89=0),1,K$2^$F89))) -> 1.6696021e-14 | L89: =$C89*IF(AND(L$2=0,$D89=0),1,L$2^$D89)*EXP($E89*(1-IF(AND(L$2=0,$F89=0),1,L$2^$F89))) -> 1.760498e-14 | M89: =$C89*IF(AND(M$2=0,$D89=0),1,M$2^$D89)*EXP($E89*(1-IF(AND(M$2=0,$F89=0),1,M$2^$F89))) -> 1.8531464e-14 | N89: =$C89*IF(AND(N$2=0,$D89=0),1,N$2^$D89)*EXP($E89*(1-IF(AND(N$2=0,$F89=0),1,N$2^$F89))) -> 1.9480384e-14 | ... CQ89: =$C89*IF(AND(CQ$2=0,$D89=0),1,CQ$2^$D89)*EXP($E89*(1-IF(AND(CQ$2=0,$F89=0),1,CQ$2^$F89))) -> 1.1383e-13

Sheet 平衡含水率
A1: 平衡含水率 | D1: Y = a·X^b · exp(c·(1 − X^d)) | H1: Y = (f − g)·(X − 0.98) / 0.02 + g | J1: 境界値チェック (RH=0.98) | N1: 境目 X0 | O1: 0.98 | P1: Parameter=2 の直線に切り替える相対湿度。プログラム（material_props.py の PowerExpIsotherm）と同じ値。変えるときは両方直す。
B2: 材料名 | C2: Parameter | D2: a | E2: b | F2: c | G2: d | H2: f | I2: g | J2: Y@0.98 (a-d式) | K2: Y@0.98 (f-g式) | L2: Δ (J-K) | M2: 0 | N2: 0.02 | O2: 0.04 | P2: 0.06 | Q2: 0.08 | R2: 0.1 | S2: 0.12 | T2: 0.14 | U2: 0.16 | V2: 0.18 | W2: 0.2 | X2: 0.22 | Y2: 0.24 | Z2: 0.26 | AA2: 0.28 | AB2: 0.3 | AC2: 0.32 | AD2: 0.34 | AE2: 0.36 | AF2: 0.38 | AG2: 0.4 | AH2: 0.42 | AI2: 0.44 | AJ2: 0.46 | AK2: 0.48 | AL2: 0.5 | AM2: 0.52 | AN2: 0.54 | AO2: 0.56 | AP2: 0.58 | AQ2: 0.6 | AR2: 0.62 | AS2: 0.64 | AT2: 0.66 | AU2: 0.68 | AV2: 0.7 | AW2: 0.72 | AX2: 0.74 | AY2: 0.76 | AZ2: 0.78 | BA2: 0.8 | BB2: 0.82 | BC2: 0.84 | BD2: 0.86 | BE2: 0.88 | BF2: 0.9 | BG2: 0.92 | BH2: 0.94 | BI2: 0.96 | BJ2: 0.961 | BK2: 0.962 | BL2: 0.963 | BM2: 0.964 | BN2: 0.965 | BO2: 0.966 | BP2: 0.967 | BQ2: 0.968 | BR2: 0.969 | BS2: 0.97 | BT2: 0.971 | BU2: 0.972 | BV2: 0.973 | BW2: 0.974 | BX2: 0.975 | BY2: 0.976 | BZ2: 0.977 | CA2: 0.978 | CB2: 0.979 | CC2: 0.98 | CD2: 0.981 | CE2: 0.982 | CF2: 0.983 | CG2: 0.984 | CH2: 0.985 | CI2: 0.986 | CJ2: 0.987 | CK2: 0.988 | CL2: 0.989 | CM2: 0.99 | CN2: 0.991 | CO2: 0.992 | CP2: 0.993 | CQ2: 0.994 | CR2: 0.995 | CS2: 0.996 | CT2: 0.997 | CU2: 0.998 | CV2: 0.999 | CW2: 1
A3: 1 | B3: =データファイル用!$B4 -> MEWS Aerated Concrete | C3: =データファイル用!K4 -> 1 | D3: =データファイル用!L4 -> 0.78743 | E3: =データファイル用!M4 -> 17.297 | F3: =データファイル用!N4 -> -0.35107 | G3: =データファイル用!O4 -> 78.553 | H3: =データファイル用!P4 -> 0 | I3: =データファイル用!Q4 -> 0 | J3: =$D3*$O$1^$E3*EXP($F3*(1-$O$1^$G3)) -> 0.41992105 | K3: =($H3-$I3)*($O$1-$O$1)/(1-$O$1)+$I3 -> 0 | L3: =IF($C3=2,$J3-$K3,"N/A") -> N/A | M3: =IF($C3=2,IF(M$2<=$O$1,$D3*IF(AND(M$2=0,$E3=0),1,M$2^$E3)*EXP($F3*(1-IF(AND(M$2=0,$G3=0),1,M$2^$G3))),($H3-$I3)*(M$2-$O$1)/(1-$O$1)+$I3),$D3*IF(AND(M$2=0,$E3=0),1,M$2^$E3)*EXP($F3*(1-IF(AND(M$2=0,$G3=0),1,M$2^$G3)))) -> 0 | N3: =IF($C3=2,IF(N$2<=$O$1,$D3*IF(AND(N$2=0,$E3=0),1,N$2^$E3)*EXP($F3*(1-IF(AND(N$2=0,$G3=0),1,N$2^$G3))),($H3-$I3)*(N$2-$O$1)/(1-$O$1)+$I3),$D3*IF(AND(N$2=0,$E3=0),1,N$2^$E3)*EXP($F3*(1-IF(AND(N$2=0,$G3=0),1,N$2^$G3)))) -> 2.2733171e-30 | O3: =IF($C3=2,IF(O$2<=$O$1,$D3*IF(AND(O$2=0,$E3=0),1,O$2^$E3)*EXP($F3*(1-IF(AND(O$2=0,$G3=0),1,O$2^$G3))),($H3-$I3)*(O$2-$O$1)/(1-$O$1)+$I3),$D3*IF(AND(O$2=0,$E3=0),1,O$2^$E3)*EXP($F3*(1-IF(AND(O$2=0,$G3=0),1,O$2^$G3)))) -> 3.6607988e-25 | P3: =IF($C3=2,IF(P$2<=$O$1,$D3*IF(AND(P$2=0,$E3=0),1,P$2^$E3)*EXP($F3*(1-IF(AND(P$2=0,$G3=0),1,P$2^$G3))),($H3-$I3)*(P$2-$O$1)/(1-$O$1)+$I3),$D3*IF(AND(P$2=0,$E3=0),1,P$2^$E3)*EXP($F3*(1-IF(AND(P$2=0,$G3=0),1,P$2^$G3)))) -> 4.0684255e-22 | Q3: =IF($C3=2,IF(Q$2<=$O$1,$D3*IF(AND(Q$2=0,$E3=0),1,Q$2^$E3)*EXP($F3*(1-IF(AND(Q$2=0,$G3=0),1,Q$2^$G3))),($H3-$I3)*(Q$2-$O$1)/(1-$O$1)+$I3),$D3*IF(AND(Q$2=0,$E3=0),1,Q$2^$E3)*EXP($F3*(1-IF(AND(Q$2=0,$G3=0),1,Q$2^$G3)))) -> 5.8951071e-20 | R3: =IF($C3=2,IF(R$2<=$O$1,$D3*IF(AND(R$2=0,$E3=0),1,R$2^$E3)*EXP($F3*(1-IF(AND(R$2=0,$G3=0),1,R$2^$G3))),($H3-$I3)*(R$2-$O$1)/(1-$O$1)+$I3),$D3*IF(AND(R$2=0,$E3=0),1,R$2^$E3)*EXP($F3*(1-IF(AND(R$2=0,$G3=0),1,R$2^$G3)))) -> 2.7973332e-18 | S3: =IF($C3=2,IF(S$2<=$O$1,$D3*IF(AND(S$2=0,$E3=0),1,S$2^$E3)*EXP($F3*(1-IF(AND(S$2=0,$G3=0),1,S$2^$G3))),($H3-$I3)*(S$2-$O$1)/(1-$O$1)+$I3),$D3*IF(AND(S$2=0,$E3=0),1,S$2^$E3)*EXP($F3*(1-IF(AND(S$2=0,$G3=0),1,S$2^$G3)))) -> 6.551522e-17 | T3: =IF($C3=2,IF(T$2<=$O$1,$D3*IF(AND(T$2=0,$E3=0),1,T$2^$E3)*EXP($F3*(1-IF(AND(T$2=0,$G3=0),1,T$2^$G3))),($H3-$I3)*(T$2-$O$1)/(1-$O$1)+$I3),$D3*IF(AND(T$2=0,$E3=0),1,T$2^$E3)*EXP($F3*(1-IF(AND(T$2=0,$G3=0),1,T$2^$G3)))) -> 9.4258566e-16 | ... CW3: =IF($C3=2,IF(CW$2<=$O$1,$D3*IF(AND(CW$2=0,$E3=0),1,CW$2^$E3)*EXP($F3*(1-IF(AND(CW$2=0,$G3=0),1,CW$2^$G3))),($H3-$I3)*(CW$2-$O$1)/(1-$O$1)+$I3),$D3*IF(AND(CW$2=0,$E3=0),1,CW$2^$E3)*EXP($F3*(1-IF(AND(CW$2=0,$G3=0),1,CW$2^$G3)))) -> 0.78743
A4: 2 | B4: =データファイル用!$B5 -> MEWS Oriented Strand Board | C4: =データファイル用!K5 -> 1 | D4: =データファイル用!L5 -> 0.83636 | E4: =データファイル用!M5 -> 4.5881 | F4: =データファイル用!N5 -> -1.0827 | G4: =データファイル用!O5 -> 40.595 | H4: =データファイル用!P5 -> 0 | I4: =データファイル用!Q5 -> 0 | J4: =$D4*$O$1^$E4*EXP($F4*(1-$O$1^$G4)) -> 0.41590671 | K4: =($H4-$I4)*($O$1-$O$1)/(1-$O$1)+$I4 -> 0 | L4: =IF($C4=2,$J4-$K4,"N/A") -> N/A | M4: =IF($C4=2,IF(M$2<=$O$1,$D4*IF(AND(M$2=0,$E4=0),1,M$2^$E4)*EXP($F4*(1-IF(AND(M$2=0,$G4=0),1,M$2^$G4))),($H4-$I4)*(M$2-$O$1)/(1-$O$1)+$I4),$D4*IF(AND(M$2=0,$E4=0),1,M$2^$E4)*EXP($F4*(1-IF(AND(M$2=0,$G4=0),1,M$2^$G4)))) -> 0 | N4: =IF($C4=2,IF(N$2<=$O$1,$D4*IF(AND(N$2=0,$E4=0),1,N$2^$E4)*EXP($F4*(1-IF(AND(N$2=0,$G4=0),1,N$2^$G4))),($H4-$I4)*(N$2-$O$1)/(1-$O$1)+$I4),$D4*IF(AND(N$2=0,$E4=0),1,N$2^$E4)*EXP($F4*(1-IF(AND(N$2=0,$G4=0),1,N$2^$G4)))) -> 4.5408624e-09 | O4: =IF($C4=2,IF(O$2<=$O$1,$D4*IF(AND(O$2=0,$E4=0),1,O$2^$E4)*EXP($F4*(1-IF(AND(O$2=0,$G4=0),1,O$2^$G4))),($H4-$I4)*(O$2-$O$1)/(1-$O$1)+$I4),$D4*IF(AND(O$2=0,$E4=0),1,O$2^$E4)*EXP($F4*(1-IF(AND(O$2=0,$G4=0),1,O$2^$G4)))) -> 1.0921796e-07 | P4: =IF($C4=2,IF(P$2<=$O$1,$D4*IF(AND(P$2=0,$E4=0),1,P$2^$E4)*EXP($F4*(1-IF(AND(P$2=0,$G4=0),1,P$2^$G4))),($H4-$I4)*(P$2-$O$1)/(1-$O$1)+$I4),$D4*IF(AND(P$2=0,$E4=0),1,P$2^$E4)*EXP($F4*(1-IF(AND(P$2=0,$G4=0),1,P$2^$G4)))) -> 7.0180809e-07 | Q4: =IF($C4=2,IF(Q$2<=$O$1,$D4*IF(AND(Q$2=0,$E4=0),1,Q$2^$E4)*EXP($F4*(1-IF(AND(Q$2=0,$G4=0),1,Q$2^$G4))),($H4-$I4)*(Q$2-$O$1)/(1-$O$1)+$I4),$D4*IF(AND(Q$2=0,$E4=0),1,Q$2^$E4)*EXP($F4*(1-IF(AND(Q$2=0,$G4=0),1,Q$2^$G4)))) -> 2.6269378e-06 | R4: =IF($C4=2,IF(R$2<=$O$1,$D4*IF(AND(R$2=0,$E4=0),1,R$2^$E4)*EXP($F4*(1-IF(AND(R$2=0,$G4=0),1,R$2^$G4))),($H4-$I4)*(R$2-$O$1)/(1-$O$1)+$I4),$D4*IF(AND(R$2=0,$E4=0),1,R$2^$E4)*EXP($F4*(1-IF(AND(R$2=0,$G4=0),1,R$2^$G4)))) -> 7.3127819e-06 | S4: =IF($C4=2,IF(S$2<=$O$1,$D4*IF(AND(S$2=0,$E4=0),1,S$2^$E4)*EXP($F4*(1-IF(AND(S$2=0,$G4=0),1,S$2^$G4))),($H4-$I4)*(S$2-$O$1)/(1-$O$1)+$I4),$D4*IF(AND(S$2=0,$E4=0),1,S$2^$E4)*EXP($F4*(1-IF(AND(S$2=0,$G4=0),1,S$2^$G4)))) -> 1.6880064e-05 | T4: =IF($C4=2,IF(T$2<=$O$1,$D4*IF(AND(T$2=0,$E4=0),1,T$2^$E4)*EXP($F4*(1-IF(AND(T$2=0,$G4=0),1,T$2^$G4))),($H4-$I4)*(T$2-$O$1)/(1-$O$1)+$I4),$D4*IF(AND(T$2=0,$E4=0),1,T$2^$E4)*EXP($F4*(1-IF(AND(T$2=0,$G4=0),1,T$2^$G4)))) -> 3.4239914e-05 | ... CW4: =IF($C4=2,IF(CW$2<=$O$1,$D4*IF(AND(CW$2=0,$E4=0),1,CW$2^$E4)*EXP($F4*(1-IF(AND(CW$2=0,$G4=0),1,CW$2^$G4))),($H4-$I4)*(CW$2-$O$1)/(1-$O$1)+$I4),$D4*IF(AND(CW$2=0,$E4=0),1,CW$2^$E4)*EXP($F4*(1-IF(AND(CW$2=0,$G4=0),1,CW$2^$G4)))) -> 0.83636
A5: 3 | B5: =データファイル用!$B6 -> MEWS Plywood | C5: =データファイル用!K6 -> 1 | D5: =データファイル用!L6 -> 0.87267 | E5: =データファイル用!M6 -> 2.3742 | F5: =データファイル用!N6 -> -1.3561 | G5: =データファイル用!O6 -> 38.492 | H5: =データファイル用!P6 -> 0 | I5: =データファイル用!Q6 -> 0 | J5: =$D5*$O$1^$E5*EXP($F5*(1-$O$1^$G5)) -> 0.39965584 | K5: =($H5-$I5)*($O$1-$O$1)/(1-$O$1)+$I5 -> 0 | L5: =IF($C5=2,$J5-$K5,"N/A") -> N/A | M5: =IF($C5=2,IF(M$2<=$O$1,$D5*IF(AND(M$2=0,$E5=0),1,M$2^$E5)*EXP($F5*(1-IF(AND(M$2=0,$G5=0),1,M$2^$G5))),($H5-$I5)*(M$2-$O$1)/(1-$O$1)+$I5),$D5*IF(AND(M$2=0,$E5=0),1,M$2^$E5)*EXP($F5*(1-IF(AND(M$2=0,$G5=0),1,M$2^$G5)))) -> 0 | N5: =IF($C5=2,IF(N$2<=$O$1,$D5*IF(AND(N$2=0,$E5=0),1,N$2^$E5)*EXP($F5*(1-IF(AND(N$2=0,$G5=0),1,N$2^$G5))),($H5-$I5)*(N$2-$O$1)/(1-$O$1)+$I5),$D5*IF(AND(N$2=0,$E5=0),1,N$2^$E5)*EXP($F5*(1-IF(AND(N$2=0,$G5=0),1,N$2^$G5)))) -> 2.0806964e-05 | O5: =IF($C5=2,IF(O$2<=$O$1,$D5*IF(AND(O$2=0,$E5=0),1,O$2^$E5)*EXP($F5*(1-IF(AND(O$2=0,$G5=0),1,O$2^$G5))),($H5-$I5)*(O$2-$O$1)/(1-$O$1)+$I5),$D5*IF(AND(O$2=0,$E5=0),1,O$2^$E5)*EXP($F5*(1-IF(AND(O$2=0,$G5=0),1,O$2^$G5)))) -> 0.00010787334 | P5: =IF($C5=2,IF(P$2<=$O$1,$D5*IF(AND(P$2=0,$E5=0),1,P$2^$E5)*EXP($F5*(1-IF(AND(P$2=0,$G5=0),1,P$2^$G5))),($H5-$I5)*(P$2-$O$1)/(1-$O$1)+$I5),$D5*IF(AND(P$2=0,$E5=0),1,P$2^$E5)*EXP($F5*(1-IF(AND(P$2=0,$G5=0),1,P$2^$G5)))) -> 0.00028248149 | Q5: =IF($C5=2,IF(Q$2<=$O$1,$D5*IF(AND(Q$2=0,$E5=0),1,Q$2^$E5)*EXP($F5*(1-IF(AND(Q$2=0,$G5=0),1,Q$2^$G5))),($H5-$I5)*(Q$2-$O$1)/(1-$O$1)+$I5),$D5*IF(AND(Q$2=0,$E5=0),1,Q$2^$E5)*EXP($F5*(1-IF(AND(Q$2=0,$G5=0),1,Q$2^$G5)))) -> 0.00055926745 | R5: =IF($C5=2,IF(R$2<=$O$1,$D5*IF(AND(R$2=0,$E5=0),1,R$2^$E5)*EXP($F5*(1-IF(AND(R$2=0,$G5=0),1,R$2^$G5))),($H5-$I5)*(R$2-$O$1)/(1-$O$1)+$I5),$D5*IF(AND(R$2=0,$E5=0),1,R$2^$E5)*EXP($F5*(1-IF(AND(R$2=0,$G5=0),1,R$2^$G5)))) -> 0.00094995558 | S5: =IF($C5=2,IF(S$2<=$O$1,$D5*IF(AND(S$2=0,$E5=0),1,S$2^$E5)*EXP($F5*(1-IF(AND(S$2=0,$G5=0),1,S$2^$G5))),($H5-$I5)*(S$2-$O$1)/(1-$O$1)+$I5),$D5*IF(AND(S$2=0,$E5=0),1,S$2^$E5)*EXP($F5*(1-IF(AND(S$2=0,$G5=0),1,S$2^$G5)))) -> 0.0014645204 | T5: =IF($C5=2,IF(T$2<=$O$1,$D5*IF(AND(T$2=0,$E5=0),1,T$2^$E5)*EXP($F5*(1-IF(AND(T$2=0,$G5=0),1,T$2^$G5))),($H5-$I5)*(T$2-$O$1)/(1-$O$1)+$I5),$D5*IF(AND(T$2=0,$E5=0),1,T$2^$E5)*EXP($F5*(1-IF(AND(T$2=0,$G5=0),1,T$2^$G5)))) -> 0.0021117402 | ... CW5: =IF($C5=2,IF(CW$2<=$O$1,$D5*IF(AND(CW$2=0,$E5=0),1,CW$2^$E5)*EXP($F5*(1-IF(AND(CW$2=0,$G5=0),1,CW$2^$G5))),($H5-$I5)*(CW$2-$O$1)/(1-$O$1)+$I5),$D5*IF(AND(CW$2=0,$E5=0),1,CW$2^$E5)*EXP($F5*(1-IF(AND(CW$2=0,$G5=0),1,CW$2^$G5)))) -> 0.87267
A6: 4 | B6: =データファイル用!$B7 -> MEWS Building Membrane IA | C6: =データファイル用!K7 -> 1 | D6: =データファイル用!L7 -> 0 | E6: =データファイル用!M7 -> 0 | F6: =データファイル用!N7 -> 0 | G6: =データファイル用!O7 -> 0 | H6: =データファイル用!P7 -> 0 | I6: =データファイル用!Q7 -> 0 | J6: =$D6*$O$1^$E6*EXP($F6*(1-$O$1^$G6)) -> 0 | K6: =($H6-$I6)*($O$1-$O$1)/(1-$O$1)+$I6 -> 0 | L6: =IF($C6=2,$J6-$K6,"N/A") -> N/A | M6: =IF($C6=2,IF(M$2<=$O$1,$D6*IF(AND(M$2=0,$E6=0),1,M$2^$E6)*EXP($F6*(1-IF(AND(M$2=0,$G6=0),1,M$2^$G6))),($H6-$I6)*(M$2-$O$1)/(1-$O$1)+$I6),$D6*IF(AND(M$2=0,$E6=0),1,M$2^$E6)*EXP($F6*(1-IF(AND(M$2=0,$G6=0),1,M$2^$G6)))) -> 0 | N6: =IF($C6=2,IF(N$2<=$O$1,$D6*IF(AND(N$2=0,$E6=0),1,N$2^$E6)*EXP($F6*(1-IF(AND(N$2=0,$G6=0),1,N$2^$G6))),($H6-$I6)*(N$2-$O$1)/(1-$O$1)+$I6),$D6*IF(AND(N$2=0,$E6=0),1,N$2^$E6)*EXP($F6*(1-IF(AND(N$2=0,$G6=0),1,N$2^$G6)))) -> 0 | O6: =IF($C6=2,IF(O$2<=$O$1,$D6*IF(AND(O$2=0,$E6=0),1,O$2^$E6)*EXP($F6*(1-IF(AND(O$2=0,$G6=0),1,O$2^$G6))),($H6-$I6)*(O$2-$O$1)/(1-$O$1)+$I6),$D6*IF(AND(O$2=0,$E6=0),1,O$2^$E6)*EXP($F6*(1-IF(AND(O$2=0,$G6=0),1,O$2^$G6)))) -> 0 | P6: =IF($C6=2,IF(P$2<=$O$1,$D6*IF(AND(P$2=0,$E6=0),1,P$2^$E6)*EXP($F6*(1-IF(AND(P$2=0,$G6=0),1,P$2^$G6))),($H6-$I6)*(P$2-$O$1)/(1-$O$1)+$I6),$D6*IF(AND(P$2=0,$E6=0),1,P$2^$E6)*EXP($F6*(1-IF(AND(P$2=0,$G6=0),1,P$2^$G6)))) -> 0 | Q6: =IF($C6=2,IF(Q$2<=$O$1,$D6*IF(AND(Q$2=0,$E6=0),1,Q$2^$E6)*EXP($F6*(1-IF(AND(Q$2=0,$G6=0),1,Q$2^$G6))),($H6-$I6)*(Q$2-$O$1)/(1-$O$1)+$I6),$D6*IF(AND(Q$2=0,$E6=0),1,Q$2^$E6)*EXP($F6*(1-IF(AND(Q$2=0,$G6=0),1,Q$2^$G6)))) -> 0 | R6: =IF($C6=2,IF(R$2<=$O$1,$D6*IF(AND(R$2=0,$E6=0),1,R$2^$E6)*EXP($F6*(1-IF(AND(R$2=0,$G6=0),1,R$2^$G6))),($H6-$I6)*(R$2-$O$1)/(1-$O$1)+$I6),$D6*IF(AND(R$2=0,$E6=0),1,R$2^$E6)*EXP($F6*(1-IF(AND(R$2=0,$G6=0),1,R$2^$G6)))) -> 0 | S6: =IF($C6=2,IF(S$2<=$O$1,$D6*IF(AND(S$2=0,$E6=0),1,S$2^$E6)*EXP($F6*(1-IF(AND(S$2=0,$G6=0),1,S$2^$G6))),($H6-$I6)*(S$2-$O$1)/(1-$O$1)+$I6),$D6*IF(AND(S$2=0,$E6=0),1,S$2^$E6)*EXP($F6*(1-IF(AND(S$2=0,$G6=0),1,S$2^$G6)))) -> 0 | T6: =IF($C6=2,IF(T$2<=$O$1,$D6*IF(AND(T$2=0,$E6=0),1,T$2^$E6)*EXP($F6*(1-IF(AND(T$2=0,$G6=0),1,T$2^$G6))),($H6-$I6)*(T$2-$O$1)/(1-$O$1)+$I6),$D6*IF(AND(T$2=0,$E6=0),1,T$2^$E6)*EXP($F6*(1-IF(AND(T$2=0,$G6=0),1,T$2^$G6)))) -> 0 | ... CW6: =IF($C6=2,IF(CW$2<=$O$1,$D6*IF(AND(CW$2=0,$E6=0),1,CW$2^$E6)*EXP($F6*(1-IF(AND(CW$2=0,$G6=0),1,CW$2^$G6))),($H6-$I6)*(CW$2-$O$1)/(1-$O$1)+$I6),$D6*IF(AND(CW$2=0,$E6=0),1,CW$2^$E6)*EXP($F6*(1-IF(AND(CW$2=0,$G6=0),1,CW$2^$G6)))) -> 0
A7: 5 | B7: =データファイル用!$B8 -> MEWS Building Membrane II | C7: =データファイル用!K8 -> 1 | D7: =データファイル用!L8 -> 0 | E7: =データファイル用!M8 -> 0 | F7: =データファイル用!N8 -> 0 | G7: =データファイル用!O8 -> 0 | H7: =データファイル用!P8 -> 0 | I7: =データファイル用!Q8 -> 0 | J7: =$D7*$O$1^$E7*EXP($F7*(1-$O$1^$G7)) -> 0 | K7: =($H7-$I7)*($O$1-$O$1)/(1-$O$1)+$I7 -> 0 | L7: =IF($C7=2,$J7-$K7,"N/A") -> N/A | M7: =IF($C7=2,IF(M$2<=$O$1,$D7*IF(AND(M$2=0,$E7=0),1,M$2^$E7)*EXP($F7*(1-IF(AND(M$2=0,$G7=0),1,M$2^$G7))),($H7-$I7)*(M$2-$O$1)/(1-$O$1)+$I7),$D7*IF(AND(M$2=0,$E7=0),1,M$2^$E7)*EXP($F7*(1-IF(AND(M$2=0,$G7=0),1,M$2^$G7)))) -> 0 | N7: =IF($C7=2,IF(N$2<=$O$1,$D7*IF(AND(N$2=0,$E7=0),1,N$2^$E7)*EXP($F7*(1-IF(AND(N$2=0,$G7=0),1,N$2^$G7))),($H7-$I7)*(N$2-$O$1)/(1-$O$1)+$I7),$D7*IF(AND(N$2=0,$E7=0),1,N$2^$E7)*EXP($F7*(1-IF(AND(N$2=0,$G7=0),1,N$2^$G7)))) -> 0 | O7: =IF($C7=2,IF(O$2<=$O$1,$D7*IF(AND(O$2=0,$E7=0),1,O$2^$E7)*EXP($F7*(1-IF(AND(O$2=0,$G7=0),1,O$2^$G7))),($H7-$I7)*(O$2-$O$1)/(1-$O$1)+$I7),$D7*IF(AND(O$2=0,$E7=0),1,O$2^$E7)*EXP($F7*(1-IF(AND(O$2=0,$G7=0),1,O$2^$G7)))) -> 0 | P7: =IF($C7=2,IF(P$2<=$O$1,$D7*IF(AND(P$2=0,$E7=0),1,P$2^$E7)*EXP($F7*(1-IF(AND(P$2=0,$G7=0),1,P$2^$G7))),($H7-$I7)*(P$2-$O$1)/(1-$O$1)+$I7),$D7*IF(AND(P$2=0,$E7=0),1,P$2^$E7)*EXP($F7*(1-IF(AND(P$2=0,$G7=0),1,P$2^$G7)))) -> 0 | Q7: =IF($C7=2,IF(Q$2<=$O$1,$D7*IF(AND(Q$2=0,$E7=0),1,Q$2^$E7)*EXP($F7*(1-IF(AND(Q$2=0,$G7=0),1,Q$2^$G7))),($H7-$I7)*(Q$2-$O$1)/(1-$O$1)+$I7),$D7*IF(AND(Q$2=0,$E7=0),1,Q$2^$E7)*EXP($F7*(1-IF(AND(Q$2=0,$G7=0),1,Q$2^$G7)))) -> 0 | R7: =IF($C7=2,IF(R$2<=$O$1,$D7*IF(AND(R$2=0,$E7=0),1,R$2^$E7)*EXP($F7*(1-IF(AND(R$2=0,$G7=0),1,R$2^$G7))),($H7-$I7)*(R$2-$O$1)/(1-$O$1)+$I7),$D7*IF(AND(R$2=0,$E7=0),1,R$2^$E7)*EXP($F7*(1-IF(AND(R$2=0,$G7=0),1,R$2^$G7)))) -> 0 | S7: =IF($C7=2,IF(S$2<=$O$1,$D7*IF(AND(S$2=0,$E7=0),1,S$2^$E7)*EXP($F7*(1-IF(AND(S$2=0,$G7=0),1,S$2^$G7))),($H7-$I7)*(S$2-$O$1)/(1-$O$1)+$I7),$D7*IF(AND(S$2=0,$E7=0),1,S$2^$E7)*EXP($F7*(1-IF(AND(S$2=0,$G7=0),1,S$2^$G7)))) -> 0 | T7: =IF($C7=2,IF(T$2<=$O$1,$D7*IF(AND(T$2=0,$E7=0),1,T$2^$E7)*EXP($F7*(1-IF(AND(T$2=0,$G7=0),1,T$2^$G7))),($H7-$I7)*(T$2-$O$1)/(1-$O$1)+$I7),$D7*IF(AND(T$2=0,$E7=0),1,T$2^$E7)*EXP($F7*(1-IF(AND(T$2=0,$G7=0),1,T$2^$G7)))) -> 0 | ... CW7: =IF($C7=2,IF(CW$2<=$O$1,$D7*IF(AND(CW$2=0,$E7=0),1,CW$2^$E7)*EXP($F7*(1-IF(AND(CW$2=0,$G7=0),1,CW$2^$G7))),($H7-$I7)*(CW$2-$O$1)/(1-$O$1)+$I7),$D7*IF(AND(CW$2=0,$E7=0),1,CW$2^$E7)*EXP($F7*(1-IF(AND(CW$2=0,$G7=0),1,CW$2^$G7)))) -> 0
A8: 6 | B8: =データファイル用!$B9 -> MEWS Building Membrane III | C8: =データファイル用!K9 -> 1 | D8: =データファイル用!L9 -> 0 | E8: =データファイル用!M9 -> 0 | F8: =データファイル用!N9 -> 0 | G8: =データファイル用!O9 -> 0 | H8: =データファイル用!P9 -> 0 | I8: =データファイル用!Q9 -> 0 | J8: =$D8*$O$1^$E8*EXP($F8*(1-$O$1^$G8)) -> 0 | K8: =($H8-$I8)*($O$1-$O$1)/(1-$O$1)+$I8 -> 0 | L8: =IF($C8=2,$J8-$K8,"N/A") -> N/A | M8: =IF($C8=2,IF(M$2<=$O$1,$D8*IF(AND(M$2=0,$E8=0),1,M$2^$E8)*EXP($F8*(1-IF(AND(M$2=0,$G8=0),1,M$2^$G8))),($H8-$I8)*(M$2-$O$1)/(1-$O$1)+$I8),$D8*IF(AND(M$2=0,$E8=0),1,M$2^$E8)*EXP($F8*(1-IF(AND(M$2=0,$G8=0),1,M$2^$G8)))) -> 0 | N8: =IF($C8=2,IF(N$2<=$O$1,$D8*IF(AND(N$2=0,$E8=0),1,N$2^$E8)*EXP($F8*(1-IF(AND(N$2=0,$G8=0),1,N$2^$G8))),($H8-$I8)*(N$2-$O$1)/(1-$O$1)+$I8),$D8*IF(AND(N$2=0,$E8=0),1,N$2^$E8)*EXP($F8*(1-IF(AND(N$2=0,$G8=0),1,N$2^$G8)))) -> 0 | O8: =IF($C8=2,IF(O$2<=$O$1,$D8*IF(AND(O$2=0,$E8=0),1,O$2^$E8)*EXP($F8*(1-IF(AND(O$2=0,$G8=0),1,O$2^$G8))),($H8-$I8)*(O$2-$O$1)/(1-$O$1)+$I8),$D8*IF(AND(O$2=0,$E8=0),1,O$2^$E8)*EXP($F8*(1-IF(AND(O$2=0,$G8=0),1,O$2^$G8)))) -> 0 | P8: =IF($C8=2,IF(P$2<=$O$1,$D8*IF(AND(P$2=0,$E8=0),1,P$2^$E8)*EXP($F8*(1-IF(AND(P$2=0,$G8=0),1,P$2^$G8))),($H8-$I8)*(P$2-$O$1)/(1-$O$1)+$I8),$D8*IF(AND(P$2=0,$E8=0),1,P$2^$E8)*EXP($F8*(1-IF(AND(P$2=0,$G8=0),1,P$2^$G8)))) -> 0 | Q8: =IF($C8=2,IF(Q$2<=$O$1,$D8*IF(AND(Q$2=0,$E8=0),1,Q$2^$E8)*EXP($F8*(1-IF(AND(Q$2=0,$G8=0),1,Q$2^$G8))),($H8-$I8)*(Q$2-$O$1)/(1-$O$1)+$I8),$D8*IF(AND(Q$2=0,$E8=0),1,Q$2^$E8)*EXP($F8*(1-IF(AND(Q$2=0,$G8=0),1,Q$2^$G8)))) -> 0 | R8: =IF($C8=2,IF(R$2<=$O$1,$D8*IF(AND(R$2=0,$E8=0),1,R$2^$E8)*EXP($F8*(1-IF(AND(R$2=0,$G8=0),1,R$2^$G8))),($H8-$I8)*(R$2-$O$1)/(1-$O$1)+$I8),$D8*IF(AND(R$2=0,$E8=0),1,R$2^$E8)*EXP($F8*(1-IF(AND(R$2=0,$G8=0),1,R$2^$G8)))) -> 0 | S8: =IF($C8=2,IF(S$2<=$O$1,$D8*IF(AND(S$2=0,$E8=0),1,S$2^$E8)*EXP($F8*(1-IF(AND(S$2=0,$G8=0),1,S$2^$G8))),($H8-$I8)*(S$2-$O$1)/(1-$O$1)+$I8),$D8*IF(AND(S$2=0,$E8=0),1,S$2^$E8)*EXP($F8*(1-IF(AND(S$2=0,$G8=0),1,S$2^$G8)))) -> 0 | T8: =IF($C8=2,IF(T$2<=$O$1,$D8*IF(AND(T$2=0,$E8=0),1,T$2^$E8)*EXP($F8*(1-IF(AND(T$2=0,$G8=0),1,T$2^$G8))),($H8-$I8)*(T$2-$O$1)/(1-$O$1)+$I8),$D8*IF(AND(T$2=0,$E8=0),1,T$2^$E8)*EXP($F8*(1-IF(AND(T$2=0,$G8=0),1,T$2^$G8)))) -> 0 | ... CW8: =IF($C8=2,IF(CW$2<=$O$1,$D8*IF(AND(CW$2=0,$E8=0),1,CW$2^$E8)*EXP($F8*(1-IF(AND(CW$2=0,$G8=0),1,CW$2^$G8))),($H8-$I8)*(CW$2-$O$1)/(1-$O$1)+$I8),$D8*IF(AND(CW$2=0,$E8=0),1,CW$2^$E8)*EXP($F8*(1-IF(AND(CW$2=0,$G8=0),1,CW$2^$G8)))) -> 0
A9: 7 | B9: =データファイル用!$B10 -> MEWS Building Membrane IVA | C9: =データファイル用!K10 -> 1 | D9: =データファイル用!L10 -> 0 | E9: =データファイル用!M10 -> 0 | F9: =データファイル用!N10 -> 0 | G9: =データファイル用!O10 -> 0 | H9: =データファイル用!P10 -> 0 | I9: =データファイル用!Q10 -> 0 | J9: =$D9*$O$1^$E9*EXP($F9*(1-$O$1^$G9)) -> 0 | K9: =($H9-$I9)*($O$1-$O$1)/(1-$O$1)+$I9 -> 0 | L9: =IF($C9=2,$J9-$K9,"N/A") -> N/A | M9: =IF($C9=2,IF(M$2<=$O$1,$D9*IF(AND(M$2=0,$E9=0),1,M$2^$E9)*EXP($F9*(1-IF(AND(M$2=0,$G9=0),1,M$2^$G9))),($H9-$I9)*(M$2-$O$1)/(1-$O$1)+$I9),$D9*IF(AND(M$2=0,$E9=0),1,M$2^$E9)*EXP($F9*(1-IF(AND(M$2=0,$G9=0),1,M$2^$G9)))) -> 0 | N9: =IF($C9=2,IF(N$2<=$O$1,$D9*IF(AND(N$2=0,$E9=0),1,N$2^$E9)*EXP($F9*(1-IF(AND(N$2=0,$G9=0),1,N$2^$G9))),($H9-$I9)*(N$2-$O$1)/(1-$O$1)+$I9),$D9*IF(AND(N$2=0,$E9=0),1,N$2^$E9)*EXP($F9*(1-IF(AND(N$2=0,$G9=0),1,N$2^$G9)))) -> 0 | O9: =IF($C9=2,IF(O$2<=$O$1,$D9*IF(AND(O$2=0,$E9=0),1,O$2^$E9)*EXP($F9*(1-IF(AND(O$2=0,$G9=0),1,O$2^$G9))),($H9-$I9)*(O$2-$O$1)/(1-$O$1)+$I9),$D9*IF(AND(O$2=0,$E9=0),1,O$2^$E9)*EXP($F9*(1-IF(AND(O$2=0,$G9=0),1,O$2^$G9)))) -> 0 | P9: =IF($C9=2,IF(P$2<=$O$1,$D9*IF(AND(P$2=0,$E9=0),1,P$2^$E9)*EXP($F9*(1-IF(AND(P$2=0,$G9=0),1,P$2^$G9))),($H9-$I9)*(P$2-$O$1)/(1-$O$1)+$I9),$D9*IF(AND(P$2=0,$E9=0),1,P$2^$E9)*EXP($F9*(1-IF(AND(P$2=0,$G9=0),1,P$2^$G9)))) -> 0 | Q9: =IF($C9=2,IF(Q$2<=$O$1,$D9*IF(AND(Q$2=0,$E9=0),1,Q$2^$E9)*EXP($F9*(1-IF(AND(Q$2=0,$G9=0),1,Q$2^$G9))),($H9-$I9)*(Q$2-$O$1)/(1-$O$1)+$I9),$D9*IF(AND(Q$2=0,$E9=0),1,Q$2^$E9)*EXP($F9*(1-IF(AND(Q$2=0,$G9=0),1,Q$2^$G9)))) -> 0 | R9: =IF($C9=2,IF(R$2<=$O$1,$D9*IF(AND(R$2=0,$E9=0),1,R$2^$E9)*EXP($F9*(1-IF(AND(R$2=0,$G9=0),1,R$2^$G9))),($H9-$I9)*(R$2-$O$1)/(1-$O$1)+$I9),$D9*IF(AND(R$2=0,$E9=0),1,R$2^$E9)*EXP($F9*(1-IF(AND(R$2=0,$G9=0),1,R$2^$G9)))) -> 0 | S9: =IF($C9=2,IF(S$2<=$O$1,$D9*IF(AND(S$2=0,$E9=0),1,S$2^$E9)*EXP($F9*(1-IF(AND(S$2=0,$G9=0),1,S$2^$G9))),($H9-$I9)*(S$2-$O$1)/(1-$O$1)+$I9),$D9*IF(AND(S$2=0,$E9=0),1,S$2^$E9)*EXP($F9*(1-IF(AND(S$2=0,$G9=0),1,S$2^$G9)))) -> 0 | T9: =IF($C9=2,IF(T$2<=$O$1,$D9*IF(AND(T$2=0,$E9=0),1,T$2^$E9)*EXP($F9*(1-IF(AND(T$2=0,$G9=0),1,T$2^$G9))),($H9-$I9)*(T$2-$O$1)/(1-$O$1)+$I9),$D9*IF(AND(T$2=0,$E9=0),1,T$2^$E9)*EXP($F9*(1-IF(AND(T$2=0,$G9=0),1,T$2^$G9)))) -> 0 | ... CW9: =IF($C9=2,IF(CW$2<=$O$1,$D9*IF(AND(CW$2=0,$E9=0),1,CW$2^$E9)*EXP($F9*(1-IF(AND(CW$2=0,$G9=0),1,CW$2^$G9))),($H9-$I9)*(CW$2-$O$1)/(1-$O$1)+$I9),$D9*IF(AND(CW$2=0,$E9=0),1,CW$2^$E9)*EXP($F9*(1-IF(AND(CW$2=0,$G9=0),1,CW$2^$G9)))) -> 0
A10: 8 | B10: =データファイル用!$B11 -> MEWS Building Membrane V A | C10: =データファイル用!K11 -> 1 | D10: =データファイル用!L11 -> 0 | E10: =データファイル用!M11 -> 0 | F10: =データファイル用!N11 -> 0 | G10: =データファイル用!O11 -> 0 | H10: =データファイル用!P11 -> 0 | I10: =データファイル用!Q11 -> 0 | J10: =$D10*$O$1^$E10*EXP($F10*(1-$O$1^$G10)) -> 0 | K10: =($H10-$I10)*($O$1-$O$1)/(1-$O$1)+$I10 -> 0 | L10: =IF($C10=2,$J10-$K10,"N/A") -> N/A | M10: =IF($C10=2,IF(M$2<=$O$1,$D10*IF(AND(M$2=0,$E10=0),1,M$2^$E10)*EXP($F10*(1-IF(AND(M$2=0,$G10=0),1,M$2^$G10))),($H10-$I10)*(M$2-$O$1)/(1-$O$1)+$I10),$D10*IF(AND(M$2=0,$E10=0),1,M$2^$E10)*EXP($F10*(1-IF(AND(M$2=0,$G10=0),1,M$2^$G10)))) -> 0 | N10: =IF($C10=2,IF(N$2<=$O$1,$D10*IF(AND(N$2=0,$E10=0),1,N$2^$E10)*EXP($F10*(1-IF(AND(N$2=0,$G10=0),1,N$2^$G10))),($H10-$I10)*(N$2-$O$1)/(1-$O$1)+$I10),$D10*IF(AND(N$2=0,$E10=0),1,N$2^$E10)*EXP($F10*(1-IF(AND(N$2=0,$G10=0),1,N$2^$G10)))) -> 0 | O10: =IF($C10=2,IF(O$2<=$O$1,$D10*IF(AND(O$2=0,$E10=0),1,O$2^$E10)*EXP($F10*(1-IF(AND(O$2=0,$G10=0),1,O$2^$G10))),($H10-$I10)*(O$2-$O$1)/(1-$O$1)+$I10),$D10*IF(AND(O$2=0,$E10=0),1,O$2^$E10)*EXP($F10*(1-IF(AND(O$2=0,$G10=0),1,O$2^$G10)))) -> 0 | P10: =IF($C10=2,IF(P$2<=$O$1,$D10*IF(AND(P$2=0,$E10=0),1,P$2^$E10)*EXP($F10*(1-IF(AND(P$2=0,$G10=0),1,P$2^$G10))),($H10-$I10)*(P$2-$O$1)/(1-$O$1)+$I10),$D10*IF(AND(P$2=0,$E10=0),1,P$2^$E10)*EXP($F10*(1-IF(AND(P$2=0,$G10=0),1,P$2^$G10)))) -> 0 | Q10: =IF($C10=2,IF(Q$2<=$O$1,$D10*IF(AND(Q$2=0,$E10=0),1,Q$2^$E10)*EXP($F10*(1-IF(AND(Q$2=0,$G10=0),1,Q$2^$G10))),($H10-$I10)*(Q$2-$O$1)/(1-$O$1)+$I10),$D10*IF(AND(Q$2=0,$E10=0),1,Q$2^$E10)*EXP($F10*(1-IF(AND(Q$2=0,$G10=0),1,Q$2^$G10)))) -> 0 | R10: =IF($C10=2,IF(R$2<=$O$1,$D10*IF(AND(R$2=0,$E10=0),1,R$2^$E10)*EXP($F10*(1-IF(AND(R$2=0,$G10=0),1,R$2^$G10))),($H10-$I10)*(R$2-$O$1)/(1-$O$1)+$I10),$D10*IF(AND(R$2=0,$E10=0),1,R$2^$E10)*EXP($F10*(1-IF(AND(R$2=0,$G10=0),1,R$2^$G10)))) -> 0 | S10: =IF($C10=2,IF(S$2<=$O$1,$D10*IF(AND(S$2=0,$E10=0),1,S$2^$E10)*EXP($F10*(1-IF(AND(S$2=0,$G10=0),1,S$2^$G10))),($H10-$I10)*(S$2-$O$1)/(1-$O$1)+$I10),$D10*IF(AND(S$2=0,$E10=0),1,S$2^$E10)*EXP($F10*(1-IF(AND(S$2=0,$G10=0),1,S$2^$G10)))) -> 0 | T10: =IF($C10=2,IF(T$2<=$O$1,$D10*IF(AND(T$2=0,$E10=0),1,T$2^$E10)*EXP($F10*(1-IF(AND(T$2=0,$G10=0),1,T$2^$G10))),($H10-$I10)*(T$2-$O$1)/(1-$O$1)+$I10),$D10*IF(AND(T$2=0,$E10=0),1,T$2^$E10)*EXP($F10*(1-IF(AND(T$2=0,$G10=0),1,T$2^$G10)))) -> 0 | ... CW10: =IF($C10=2,IF(CW$2<=$O$1,$D10*IF(AND(CW$2=0,$E10=0),1,CW$2^$E10)*EXP($F10*(1-IF(AND(CW$2=0,$G10=0),1,CW$2^$G10))),($H10-$I10)*(CW$2-$O$1)/(1-$O$1)+$I10),$D10*IF(AND(CW$2=0,$E10=0),1,CW$2^$E10)*EXP($F10*(1-IF(AND(CW$2=0,$G10=0),1,CW$2^$G10)))) -> 0
A11: 9 | B11: =データファイル用!$B12 -> MEWS Building Membrane V C | C11: =データファイル用!K12 -> 1 | D11: =データファイル用!L12 -> 0 | E11: =データファイル用!M12 -> 0 | F11: =データファイル用!N12 -> 0 | G11: =データファイル用!O12 -> 0 | H11: =データファイル用!P12 -> 0 | I11: =データファイル用!Q12 -> 0 | J11: =$D11*$O$1^$E11*EXP($F11*(1-$O$1^$G11)) -> 0 | K11: =($H11-$I11)*($O$1-$O$1)/(1-$O$1)+$I11 -> 0 | L11: =IF($C11=2,$J11-$K11,"N/A") -> N/A | M11: =IF($C11=2,IF(M$2<=$O$1,$D11*IF(AND(M$2=0,$E11=0),1,M$2^$E11)*EXP($F11*(1-IF(AND(M$2=0,$G11=0),1,M$2^$G11))),($H11-$I11)*(M$2-$O$1)/(1-$O$1)+$I11),$D11*IF(AND(M$2=0,$E11=0),1,M$2^$E11)*EXP($F11*(1-IF(AND(M$2=0,$G11=0),1,M$2^$G11)))) -> 0 | N11: =IF($C11=2,IF(N$2<=$O$1,$D11*IF(AND(N$2=0,$E11=0),1,N$2^$E11)*EXP($F11*(1-IF(AND(N$2=0,$G11=0),1,N$2^$G11))),($H11-$I11)*(N$2-$O$1)/(1-$O$1)+$I11),$D11*IF(AND(N$2=0,$E11=0),1,N$2^$E11)*EXP($F11*(1-IF(AND(N$2=0,$G11=0),1,N$2^$G11)))) -> 0 | O11: =IF($C11=2,IF(O$2<=$O$1,$D11*IF(AND(O$2=0,$E11=0),1,O$2^$E11)*EXP($F11*(1-IF(AND(O$2=0,$G11=0),1,O$2^$G11))),($H11-$I11)*(O$2-$O$1)/(1-$O$1)+$I11),$D11*IF(AND(O$2=0,$E11=0),1,O$2^$E11)*EXP($F11*(1-IF(AND(O$2=0,$G11=0),1,O$2^$G11)))) -> 0 | P11: =IF($C11=2,IF(P$2<=$O$1,$D11*IF(AND(P$2=0,$E11=0),1,P$2^$E11)*EXP($F11*(1-IF(AND(P$2=0,$G11=0),1,P$2^$G11))),($H11-$I11)*(P$2-$O$1)/(1-$O$1)+$I11),$D11*IF(AND(P$2=0,$E11=0),1,P$2^$E11)*EXP($F11*(1-IF(AND(P$2=0,$G11=0),1,P$2^$G11)))) -> 0 | Q11: =IF($C11=2,IF(Q$2<=$O$1,$D11*IF(AND(Q$2=0,$E11=0),1,Q$2^$E11)*EXP($F11*(1-IF(AND(Q$2=0,$G11=0),1,Q$2^$G11))),($H11-$I11)*(Q$2-$O$1)/(1-$O$1)+$I11),$D11*IF(AND(Q$2=0,$E11=0),1,Q$2^$E11)*EXP($F11*(1-IF(AND(Q$2=0,$G11=0),1,Q$2^$G11)))) -> 0 | R11: =IF($C11=2,IF(R$2<=$O$1,$D11*IF(AND(R$2=0,$E11=0),1,R$2^$E11)*EXP($F11*(1-IF(AND(R$2=0,$G11=0),1,R$2^$G11))),($H11-$I11)*(R$2-$O$1)/(1-$O$1)+$I11),$D11*IF(AND(R$2=0,$E11=0),1,R$2^$E11)*EXP($F11*(1-IF(AND(R$2=0,$G11=0),1,R$2^$G11)))) -> 0 | S11: =IF($C11=2,IF(S$2<=$O$1,$D11*IF(AND(S$2=0,$E11=0),1,S$2^$E11)*EXP($F11*(1-IF(AND(S$2=0,$G11=0),1,S$2^$G11))),($H11-$I11)*(S$2-$O$1)/(1-$O$1)+$I11),$D11*IF(AND(S$2=0,$E11=0),1,S$2^$E11)*EXP($F11*(1-IF(AND(S$2=0,$G11=0),1,S$2^$G11)))) -> 0 | T11: =IF($C11=2,IF(T$2<=$O$1,$D11*IF(AND(T$2=0,$E11=0),1,T$2^$E11)*EXP($F11*(1-IF(AND(T$2=0,$G11=0),1,T$2^$G11))),($H11-$I11)*(T$2-$O$1)/(1-$O$1)+$I11),$D11*IF(AND(T$2=0,$E11=0),1,T$2^$E11)*EXP($F11*(1-IF(AND(T$2=0,$G11=0),1,T$2^$G11)))) -> 0 | ... CW11: =IF($C11=2,IF(CW$2<=$O$1,$D11*IF(AND(CW$2=0,$E11=0),1,CW$2^$E11)*EXP($F11*(1-IF(AND(CW$2=0,$G11=0),1,CW$2^$G11))),($H11-$I11)*(CW$2-$O$1)/(1-$O$1)+$I11),$D11*IF(AND(CW$2=0,$E11=0),1,CW$2^$E11)*EXP($F11*(1-IF(AND(CW$2=0,$G11=0),1,CW$2^$G11)))) -> 0
A12: 10 | B12: =データファイル用!$B13 -> MEWS Building Membrane VI | C12: =データファイル用!K13 -> 1 | D12: =データファイル用!L13 -> 0 | E12: =データファイル用!M13 -> 0 | F12: =データファイル用!N13 -> 0 | G12: =データファイル用!O13 -> 0 | H12: =データファイル用!P13 -> 0 | I12: =データファイル用!Q13 -> 0 | J12: =$D12*$O$1^$E12*EXP($F12*(1-$O$1^$G12)) -> 0 | K12: =($H12-$I12)*($O$1-$O$1)/(1-$O$1)+$I12 -> 0 | L12: =IF($C12=2,$J12-$K12,"N/A") -> N/A | M12: =IF($C12=2,IF(M$2<=$O$1,$D12*IF(AND(M$2=0,$E12=0),1,M$2^$E12)*EXP($F12*(1-IF(AND(M$2=0,$G12=0),1,M$2^$G12))),($H12-$I12)*(M$2-$O$1)/(1-$O$1)+$I12),$D12*IF(AND(M$2=0,$E12=0),1,M$2^$E12)*EXP($F12*(1-IF(AND(M$2=0,$G12=0),1,M$2^$G12)))) -> 0 | N12: =IF($C12=2,IF(N$2<=$O$1,$D12*IF(AND(N$2=0,$E12=0),1,N$2^$E12)*EXP($F12*(1-IF(AND(N$2=0,$G12=0),1,N$2^$G12))),($H12-$I12)*(N$2-$O$1)/(1-$O$1)+$I12),$D12*IF(AND(N$2=0,$E12=0),1,N$2^$E12)*EXP($F12*(1-IF(AND(N$2=0,$G12=0),1,N$2^$G12)))) -> 0 | O12: =IF($C12=2,IF(O$2<=$O$1,$D12*IF(AND(O$2=0,$E12=0),1,O$2^$E12)*EXP($F12*(1-IF(AND(O$2=0,$G12=0),1,O$2^$G12))),($H12-$I12)*(O$2-$O$1)/(1-$O$1)+$I12),$D12*IF(AND(O$2=0,$E12=0),1,O$2^$E12)*EXP($F12*(1-IF(AND(O$2=0,$G12=0),1,O$2^$G12)))) -> 0 | P12: =IF($C12=2,IF(P$2<=$O$1,$D12*IF(AND(P$2=0,$E12=0),1,P$2^$E12)*EXP($F12*(1-IF(AND(P$2=0,$G12=0),1,P$2^$G12))),($H12-$I12)*(P$2-$O$1)/(1-$O$1)+$I12),$D12*IF(AND(P$2=0,$E12=0),1,P$2^$E12)*EXP($F12*(1-IF(AND(P$2=0,$G12=0),1,P$2^$G12)))) -> 0 | Q12: =IF($C12=2,IF(Q$2<=$O$1,$D12*IF(AND(Q$2=0,$E12=0),1,Q$2^$E12)*EXP($F12*(1-IF(AND(Q$2=0,$G12=0),1,Q$2^$G12))),($H12-$I12)*(Q$2-$O$1)/(1-$O$1)+$I12),$D12*IF(AND(Q$2=0,$E12=0),1,Q$2^$E12)*EXP($F12*(1-IF(AND(Q$2=0,$G12=0),1,Q$2^$G12)))) -> 0 | R12: =IF($C12=2,IF(R$2<=$O$1,$D12*IF(AND(R$2=0,$E12=0),1,R$2^$E12)*EXP($F12*(1-IF(AND(R$2=0,$G12=0),1,R$2^$G12))),($H12-$I12)*(R$2-$O$1)/(1-$O$1)+$I12),$D12*IF(AND(R$2=0,$E12=0),1,R$2^$E12)*EXP($F12*(1-IF(AND(R$2=0,$G12=0),1,R$2^$G12)))) -> 0 | S12: =IF($C12=2,IF(S$2<=$O$1,$D12*IF(AND(S$2=0,$E12=0),1,S$2^$E12)*EXP($F12*(1-IF(AND(S$2=0,$G12=0),1,S$2^$G12))),($H12-$I12)*(S$2-$O$1)/(1-$O$1)+$I12),$D12*IF(AND(S$2=0,$E12=0),1,S$2^$E12)*EXP($F12*(1-IF(AND(S$2=0,$G12=0),1,S$2^$G12)))) -> 0 | T12: =IF($C12=2,IF(T$2<=$O$1,$D12*IF(AND(T$2=0,$E12=0),1,T$2^$E12)*EXP($F12*(1-IF(AND(T$2=0,$G12=0),1,T$2^$G12))),($H12-$I12)*(T$2-$O$1)/(1-$O$1)+$I12),$D12*IF(AND(T$2=0,$E12=0),1,T$2^$E12)*EXP($F12*(1-IF(AND(T$2=0,$G12=0),1,T$2^$G12)))) -> 0 | ... CW12: =IF($C12=2,IF(CW$2<=$O$1,$D12*IF(AND(CW$2=0,$E12=0),1,CW$2^$E12)*EXP($F12*(1-IF(AND(CW$2=0,$G12=0),1,CW$2^$G12))),($H12-$I12)*(CW$2-$O$1)/(1-$O$1)+$I12),$D12*IF(AND(CW$2=0,$E12=0),1,CW$2^$E12)*EXP($F12*(1-IF(AND(CW$2=0,$G12=0),1,CW$2^$G12)))) -> 0
A13: 11 | B13: =データファイル用!$B14 -> MEWS Building Membrane VII | C13: =データファイル用!K14 -> 1 | D13: =データファイル用!L14 -> 0 | E13: =データファイル用!M14 -> 0 | F13: =データファイル用!N14 -> 0 | G13: =データファイル用!O14 -> 0 | H13: =データファイル用!P14 -> 0 | I13: =データファイル用!Q14 -> 0 | J13: =$D13*$O$1^$E13*EXP($F13*(1-$O$1^$G13)) -> 0 | K13: =($H13-$I13)*($O$1-$O$1)/(1-$O$1)+$I13 -> 0 | L13: =IF($C13=2,$J13-$K13,"N/A") -> N/A | M13: =IF($C13=2,IF(M$2<=$O$1,$D13*IF(AND(M$2=0,$E13=0),1,M$2^$E13)*EXP($F13*(1-IF(AND(M$2=0,$G13=0),1,M$2^$G13))),($H13-$I13)*(M$2-$O$1)/(1-$O$1)+$I13),$D13*IF(AND(M$2=0,$E13=0),1,M$2^$E13)*EXP($F13*(1-IF(AND(M$2=0,$G13=0),1,M$2^$G13)))) -> 0 | N13: =IF($C13=2,IF(N$2<=$O$1,$D13*IF(AND(N$2=0,$E13=0),1,N$2^$E13)*EXP($F13*(1-IF(AND(N$2=0,$G13=0),1,N$2^$G13))),($H13-$I13)*(N$2-$O$1)/(1-$O$1)+$I13),$D13*IF(AND(N$2=0,$E13=0),1,N$2^$E13)*EXP($F13*(1-IF(AND(N$2=0,$G13=0),1,N$2^$G13)))) -> 0 | O13: =IF($C13=2,IF(O$2<=$O$1,$D13*IF(AND(O$2=0,$E13=0),1,O$2^$E13)*EXP($F13*(1-IF(AND(O$2=0,$G13=0),1,O$2^$G13))),($H13-$I13)*(O$2-$O$1)/(1-$O$1)+$I13),$D13*IF(AND(O$2=0,$E13=0),1,O$2^$E13)*EXP($F13*(1-IF(AND(O$2=0,$G13=0),1,O$2^$G13)))) -> 0 | P13: =IF($C13=2,IF(P$2<=$O$1,$D13*IF(AND(P$2=0,$E13=0),1,P$2^$E13)*EXP($F13*(1-IF(AND(P$2=0,$G13=0),1,P$2^$G13))),($H13-$I13)*(P$2-$O$1)/(1-$O$1)+$I13),$D13*IF(AND(P$2=0,$E13=0),1,P$2^$E13)*EXP($F13*(1-IF(AND(P$2=0,$G13=0),1,P$2^$G13)))) -> 0 | Q13: =IF($C13=2,IF(Q$2<=$O$1,$D13*IF(AND(Q$2=0,$E13=0),1,Q$2^$E13)*EXP($F13*(1-IF(AND(Q$2=0,$G13=0),1,Q$2^$G13))),($H13-$I13)*(Q$2-$O$1)/(1-$O$1)+$I13),$D13*IF(AND(Q$2=0,$E13=0),1,Q$2^$E13)*EXP($F13*(1-IF(AND(Q$2=0,$G13=0),1,Q$2^$G13)))) -> 0 | R13: =IF($C13=2,IF(R$2<=$O$1,$D13*IF(AND(R$2=0,$E13=0),1,R$2^$E13)*EXP($F13*(1-IF(AND(R$2=0,$G13=0),1,R$2^$G13))),($H13-$I13)*(R$2-$O$1)/(1-$O$1)+$I13),$D13*IF(AND(R$2=0,$E13=0),1,R$2^$E13)*EXP($F13*(1-IF(AND(R$2=0,$G13=0),1,R$2^$G13)))) -> 0 | S13: =IF($C13=2,IF(S$2<=$O$1,$D13*IF(AND(S$2=0,$E13=0),1,S$2^$E13)*EXP($F13*(1-IF(AND(S$2=0,$G13=0),1,S$2^$G13))),($H13-$I13)*(S$2-$O$1)/(1-$O$1)+$I13),$D13*IF(AND(S$2=0,$E13=0),1,S$2^$E13)*EXP($F13*(1-IF(AND(S$2=0,$G13=0),1,S$2^$G13)))) -> 0 | T13: =IF($C13=2,IF(T$2<=$O$1,$D13*IF(AND(T$2=0,$E13=0),1,T$2^$E13)*EXP($F13*(1-IF(AND(T$2=0,$G13=0),1,T$2^$G13))),($H13-$I13)*(T$2-$O$1)/(1-$O$1)+$I13),$D13*IF(AND(T$2=0,$E13=0),1,T$2^$E13)*EXP($F13*(1-IF(AND(T$2=0,$G13=0),1,T$2^$G13)))) -> 0 | ... CW13: =IF($C13=2,IF(CW$2<=$O$1,$D13*IF(AND(CW$2=0,$E13=0),1,CW$2^$E13)*EXP($F13*(1-IF(AND(CW$2=0,$G13=0),1,CW$2^$G13))),($H13-$I13)*(CW$2-$O$1)/(1-$O$1)+$I13),$D13*IF(AND(CW$2=0,$E13=0),1,CW$2^$E13)*EXP($F13*(1-IF(AND(CW$2=0,$G13=0),1,CW$2^$G13)))) -> 0
